Workbook
Name SegmentaciónDeDatos_Año: #N/A
Name SegmentaciónDeDatos_Año1: #N/A
Name SegmentaciónDeDatos_Grupo_Etario: #N/A
Name SegmentaciónDeDatos_Grupo_Etario1: #N/A

Sheet Poblacion_Estudio (2)
A1: Año | B1: Grupo Etario | C1: Población Total | D1: Población Femenina
A2: 1996 | B2: 0-4 | C2: 2669011.1 | D2: 1308550.8
A3: 1997 | B3: 0-4 | C3: 2689637 | D3: 1317732.9 | F3: Suma de Población Total | G3: Etiquetas de columna
A4: 1998 | B4: 0-4 | C4: 2707580.5 | D4: 1325697.9 | F4: Etiquetas de fila | G4: 5-14 | H4: Total general | J4: Año | K4: Poblacion Femenina | L4: Poblacion Total | O4: =+G4 -> 5-14
A5: 1999 | B5: 0-4 | C5: 2723058.5 | D5: 1332529 | F5: 1996 | G5: 5336689.3 | H5: 5336689.3 | J5: 1996 | K5: =+G5 -> 5336689.3
A6: 2000 | B6: 0-4 | C6: 2736288 | D6: 1338309 | F6: 1997 | G6: 5352218.2 | H6: 5352218.2 | J6: 1997 | K6: =+G6 -> 5352218.2
A7: 2001 | B7: 0-4 | C7: 2747486 | D7: 1343121 | F7: 1998 | G7: 5360232.6 | H7: 5360232.6 | J7: 1998 | K7: =+G7 -> 5360232.6
A8: 2002 | B8: 0-4 | C8: 2756879 | D8: 1347045 | F8: 1999 | G8: 5362927.5 | H8: 5362927.5 | J8: 1999 | K8: =+G8 -> 5362927.5
A9: 2003 | B9: 0-4 | C9: 2764684 | D9: 1350164 | F9: 2000 | G9: 5362498 | H9: 5362498 | J9: 2000 | K9: =+G9 -> 5362498
A10: 2004 | B10: 0-4 | C10: 2770821 | D10: 1352508 | F10: 2001 | G10: 5361139 | H10: 5361139 | J10: 2001 | K10: =+G10 -> 5361139
A11: 2005 | B11: 0-4 | C11: 2774961 | D11: 1353852 | F11: 2002 | G11: 5361107 | H11: 5361107 | J11: 2002 | K11: =+G11 -> 5361107
A12: 2006 | B12: 0-4 | C12: 2777568 | D12: 1354432 | F12: 2003 | G12: 5364597 | H12: 5364597 | J12: 2003 | K12: =+G12 -> 5364597
A13: 2007 | B13: 0-4 | C13: 2778731 | D13: 1354234 | F13: 2004 | G13: 5372677 | H13: 5372677 | J13: 2004 | K13: =+G13 -> 5372677
A14: 2008 | B14: 0-4 | C14: 2778239 | D14: 1353145 | F14: 2005 | G14: 5386812 | H14: 5386812 | J14: 2005 | K14: =+G14 -> 5386812
A15: 2009 | B15: 0-4 | C15: 2775920 | D15: 1351158 | F15: 2006 | G15: 5407717 | H15: 5407717 | J15: 2006 | K15: =+G15 -> 5407717
A16: 2010 | B16: 0-4 | C16: 2771760 | D16: 1348289 | F16: 2007 | G16: 5427910 | H16: 5427910 | J16: 2007 | K16: =+G16 -> 5427910
... A59: 1998 | B59: 5-14 | C59: 5360232.6 | D59: 2628255.5 | F59: 2050 | G59: 4837414 | H59: 4837414 | J59: 2050 | K59: =+G59 -> 4837414
A60: 1999 | B60: 5-14 | C60: 5362927.5 | D60: 2628380.2 | F60: Total general | G60: 2.9300483e+08 | H60: 2.9300483e+08
A61: 2000 | B61: 5-14 | C61: 5362498 | D61: 2626661
A62: 2001 | B62: 5-14 | C62: 5361139 | D62: 2624275
A63: 2002 | B63: 5-14 | C63: 5361107 | D63: 2622422
A64: 2003 | B64: 5-14 | C64: 5364597 | D64: 2622279
A65: 2004 | B65: 5-14 | C65: 5372677 | D65: 2624530
A66: 2005 | B66: 5-14 | C66: 5386812 | D66: 2629864
A67: 2006 | B67: 5-14 | C67: 5407717 | D67: 2638747
A68: 2007 | B68: 5-14 | C68: 5427910 | D68: 2647233
A69: 2008 | B69: 5-14 | C69: 5448390 | D69: 2655740
A70: 2009 | B70: 5-14 | C70: 5469822 | D70: 2664671
A71: 2010 | B71: 5-14 | C71: 5492408 | D71: 2674173
A72: 2011 | B72: 5-14 | C72: 5516288 | D72: 2684312
... A386: 2050 | B386: 75+ | C386: 3804544 | D386: 1985266

Sheet TDM_Mujeres
A1: Tabla de Decrecimiento Multiple Total- Poblacion Femenina
A3: Año | B3: 1996 | E3: Tabla de Decrecimiento Multiple Todas las Causas | O3: 100000
F4: Poblacion Femenina
B5: Valores | L5: Tasa Central de Decrecimiento | M5: Tasa Instantánea de Decrecimiento
A6: Grupo Etario | B6: Máx. de Población | C6: Suma de Fallecimientos | E6: Año | F6: Grupo Etario | G6: lx(T) | H6: dx(T) | I6: qx(T) | J6: Px(T) | K6: Lx(T) | L6: mx(T) | M6: µ(X) | N6: Proporcion del Grupo Etario Vs Poblacion Total | O6: Poblacion en base a 100.000 Personas | P6: Poblacion Estimada | Q6: Fallecimientos Totales
A7: 0-4 | B7: 1308550.8 | C7: 5092 | E7: =+$B$3 -> 1996 | F7: =+A7 -> 0-4 | G7: =+B7 -> 1308550.8 | H7: =+C7 -> 5092 | I7: =+H7/G7 -> 0.0038913278 | J7: =1-I7 -> 0.99610867 | K7: =+G7-(0.5*H7) -> 1306004.8 | L7: =+H7/K7 -> 0.0038989137 | M7: =+H7/(2*G7) -> 0.0019456639 | N7: =+G7/$G$14 -> 0.11562177 | O7: =+N7*$O$3 -> 11562.177 | P7: 100000 | Q7: =+P7*I7 -> 389.13278
A8: 5-14 | B8: 2617766.7 | C8: 569 | E8: =+$B$3 -> 1996 | F8: =+A8 -> 5-14 | G8: =+B8 -> 2617766.7 | H8: =+C8 -> 569 | I8: =+H8/G8 -> 0.00021736085 | J8: =1-I8 -> 0.99978264 | K8: =+G8-(0.5*H8) -> 2617482.2 | L8: =+H8/K8 -> 0.00021738447 | M8: =+(H7+H8)/(2*G8) -> 0.0010812652 | N8: =+G8/$G$14 -> 0.23130231 | O8: =+N8*$O$3 -> 23130.231 | P8: =+P7-Q7 -> 99610.867 | Q8: =+P8*I8 -> 21.651503
A9: 15-24 | B9: 2136825.7 | C9: 790 | E9: =+$B$3 -> 1996 | F9: =+A9 -> 15-24 | G9: =+B9 -> 2136825.7 | H9: =+C9 -> 790 | I9: =+H9/G9 -> 0.00036970727 | J9: =1-I9 -> 0.99963029 | K9: =+G9-(0.5*H9) -> 2136430.7 | L9: =+H9/K9 -> 0.00036977563 | M9: =+(H8+H9)/(2*G9) -> 0.00031799505 | N9: =+G9/$G$14 -> 0.18880701 | O9: =+N9*$O$3 -> 18880.701 | P9: =+P8-Q8 -> 99589.216 | Q9: =+P9*I9 -> 36.818857
A10: 25-44 | B10: 3245545.3 | C10: 2882 | E10: =+$B$3 -> 1996 | F10: =+A10 -> 25-44 | G10: =+B10 -> 3245545.3 | H10: =+C10 -> 2882 | I10: =+H10/G10 -> 0.00088798638 | J10: =1-I10 -> 0.99911201 | K10: =+G10-(0.5*H10) -> 3244104.3 | L10: =+H10/K10 -> 0.00088838081 | M10: =+(H9+H10)/(2*G10) -> 0.00056569847 | N10: =+G10/$G$14 -> 0.28677197 | O10: =+N10*$O$3 -> 28677.197 | P10: =+P9-Q9 -> 99552.397 | Q10: =+P10*I10 -> 88.401172
A11: 45-64 | B11: 1448878 | C11: 6671 | E11: =+$B$3 -> 1996 | F11: =+A11 -> 45-64 | G11: =+B11 -> 1448878 | H11: =+C11 -> 6671 | I11: =+H11/G11 -> 0.0046042525 | J11: =1-I11 -> 0.99539575 | K11: =+G11-(0.5*H11) -> 1445542.5 | L11: =+H11/K11 -> 0.0046148766 | M11: =+(H10+H11)/(2*G11) -> 0.003296689 | N11: =+G11/$G$14 -> 0.12802089 | O11: =+N11*$O$3 -> 12802.089 | P11: =+P10-Q10 -> 99463.996 | Q11: =+P11*I11 -> 457.95735
A12: 65-74 | B12: 373487.34 | C12: 6002 | E12: =+$B$3 -> 1996 | F12: =+A12 -> 65-74 | G12: =+B12 -> 373487.34 | H12: =+C12 -> 6002 | I12: =+H12/G12 -> 0.016070156 | J12: =1-I12 -> 0.98392984 | K12: =+G12-(0.5*H12) -> 370486.34 | L12: =+H12/K12 -> 0.016200327 | M12: =+(H11+H12)/(2*G12) -> 0.016965769 | N12: =+G12/$G$14 -> 0.033000833 | O12: =+N12*$O$3 -> 3300.0833 | P12: =+P11-Q11 -> 99006.038 | Q12: =+P12*I12 -> 1591.0425
A13: 75+ | B13: 186458.59 | C13: 11555 | E13: =+$B$3 -> 1996 | F13: =+A13 -> 75+ | G13: =+B13 -> 186458.59 | H13: =+C13 -> 11555 | I13: =+H13/G13 -> 0.061970866 | J13: =1-I13 -> 0.93802913 | K13: =+G13-(0.5*H13) -> 180681.09 | L13: =+H13/K13 -> 0.063952461 | M13: =+(H12+H13)/(2*G13) -> 0.04708016 | N13: =+G13/$G$14 -> 0.016475227 | O13: =+N13*$O$3 -> 1647.5227 | P13: =+P12-Q12 -> 97414.996 | Q13: =+P13*I13 -> 6036.8917
B14: =+SUM(B7:B13) -> 11317512 | C14: =+SUM(C7:C13) -> 33561 | E14: Totales | G14: =+SUM(G7:G13) -> 11317512 | H14: =+SUM(H7:H13) -> 33561 | I14: =+H14/G14 -> 0.0029654043
E17: Gráficos
J18: Fallecimientos Totales sexo Femenino por cada 100.000 personas
E19: Población Total Femenina por cada 100.000 personas
E35: Comparaciones entre Probabilidades, Tasas Centrales y Tasas Instantáneas, por cualquier causa de decrecimiento | J35: Población y Probabilidad de Decrecimiento Total, por cualquier causa de decrecimiento
M36: Probabilidad de Decrecimiento por Cualquier causa - Sexo Femenino

Sheet TDM_Mujeres_Causa
A1: Año | B1: 1996 | T1: Tabla de Decrecimiento Multiple
T2: Poblacion Femenina
A3: Suma de Fallecimientos | C3: Posicion
A4: Grupo Etario | B4: Población | C4: 1 | D4: 2 | E4: 3 | F4: 4 | G4: 5 | H4: 6 | I4: 7 | J4: 8 | K4: 9 | L4: 10 | M4: 11 | N4: 12 | O4: 13 | P4: 14 | Q4: 15 | S4: Año | T4: Grupo Etario | U4: lx(T) | V4: =+CONCATENATE("dx","(",C4,")") -> dx(1) | W4: =+CONCATENATE("dx","(",D4,")") -> dx(2) | X4: =+CONCATENATE("dx","(",E4,")") -> dx(3) | Y4: =+CONCATENATE("dx","(",F4,")") -> dx(4) | Z4: =+CONCATENATE("dx","(",G4,")") -> dx(5) | AA4: =+CONCATENATE("dx","(",H4,")") -> dx(6) | AB4: =+CONCATENATE("dx","(",I4,")") -> dx(7) | AC4: =+CONCATENATE("dx","(",J4,")") -> dx(8) | ... AJ4: =+CONCATENATE("dx","(",Q4,")") -> dx(15) | AK4: dx(T) | AL4: =+CONCATENATE("qx","(",C4,")") -> qx(1) | AM4: =+CONCATENATE("qx","(",D4,")") -> qx(2) | AN4: =+CONCATENATE("qx","(",E4,")") -> qx(3) | AO4: =+CONCATENATE("qx","(",F4,")") -> qx(4) | AP4: =+CONCATENATE("qx","(",G4,")") -> qx(5) | AQ4: =+CONCATENATE("qx","(",H4,")") -> qx(6) | AR4: =+CONCATENATE("qx","(",I4,")") -> qx(7) | AS4: =+CONCATENATE("qx","(",J4,")") -> qx(8) | ... AZ4: =+CONCATENATE("qx","(",Q4,")") -> qx(15) | BA4: =+CONCATENATE("qx","(T)") -> qx(T) | BB4: Lx(T) | BC4: =+CONCATENATE("mx","(",C4,")") -> mx(1) | BD4: =+CONCATENATE("mx","(",D4,")") -> mx(2) | BE4: =+CONCATENATE("mx","(",E4,")") -> mx(3) | BF4: =+CONCATENATE("mx","(",F4,")") -> mx(4) | BG4: =+CONCATENATE("mx","(",G4,")") -> mx(5) | BH4: =+CONCATENATE("mx","(",H4,")") -> mx(6) | BI4: =+CONCATENATE("mx","(",I4,")") -> mx(7) | BJ4: =+CONCATENATE("mx","(",J4,")") -> mx(8) | ... BQ4: =+CONCATENATE("mx","(",Q4,")") -> mx(15) | BR4: =+CONCATENATE("µ(X)",C4) -> µ(X)1 | BS4: =+CONCATENATE("µ(X)",D4) -> µ(X)2 | BT4: =+CONCATENATE("µ(X)",E4) -> µ(X)3 | BU4: =+CONCATENATE("µ(X)",F4) -> µ(X)4 | BV4: =+CONCATENATE("µ(X)",G4) -> µ(X)5 | BW4: =+CONCATENATE("µ(X)",H4) -> µ(X)6 | BX4: =+CONCATENATE("µ(X)",I4) -> µ(X)7 | BY4: =+CONCATENATE("µ(X)",J4) -> µ(X)8 | ... CF4: =+CONCATENATE("µ(X)",Q4) -> µ(X)15
A5: 0-4 | B5: 1308550.8 | C5: 38 | D5: 62 | E5: 6 | F5: 6 | G5: 2365 | H5: 285 | I5: 63 | J5: 367 | K5: 761 | L5: 1081 | M5: 12 | N5: 12 | O5: 0 | P5: 11 | Q5: 23 | S5: =+$B$1 -> 1996 | T5: =+A5 -> 0-4 | U5: =+B5 -> 1308550.8 | V5: =+C5 -> 38 | W5: =+D5 -> 62 | X5: =+E5 -> 6 | Y5: =+F5 -> 6 | Z5: =+G5 -> 2365 | AA5: =+H5 -> 285 | ... AJ5: =+Q5 -> 23 | AK5: =+SUM(V5:AJ5) -> 5092 | AL5: =+V5/$U5 -> 2.9039759e-05 | AM5: =+W5/$U5 -> 4.738066e-05 | AN5: =+X5/$U5 -> 4.5852252e-06 | AO5: =+Y5/$U5 -> 4.5852252e-06 | AP5: =+Z5/$U5 -> 0.0018073429 | AQ5: =+AA5/$U5 -> 0.0002177982 | AR5: =+AB5/$U5 -> 4.8144864e-05 | AS5: =+AC5/$U5 -> 0.00028046294 | ... AZ5: =+AJ5/$U5 -> 1.7576697e-05 | BA5: =+AK5/U5 -> 0.0038913278 | BB5: =+U5-(0.5*AK5) -> 1306004.8 | BC5: =+AL5/(1-(0.5*$BA5)) -> 2.9096371e-05 | BD5: =+AM5/(1-(0.5*$BA5)) -> 4.7473027e-05 | BE5: =+AN5/(1-(0.5*$BA5)) -> 4.5941639e-06 | BF5: =+AO5/(1-(0.5*$BA5)) -> 4.5941639e-06 | BG5: =+AP5/(1-(0.5*$BA5)) -> 0.0018108663 | BH5: =+AQ5/(1-(0.5*$BA5)) -> 0.00021822278 | BI5: =+AR5/(1-(0.5*$BA5)) -> 4.8238721e-05 | BJ5: =+AS5/(1-(0.5*$BA5)) -> 0.00028100969 | ... BQ5: =+AZ5/(1-(0.5*$BA5)) -> 1.7610962e-05 | BR5: =+V5/(2*$U5) -> 1.451988e-05 | BS5: =+W5/(2*$U5) -> 2.369033e-05 | BT5: =+X5/(2*$U5) -> 2.2926126e-06 | BU5: =+Y5/(2*$U5) -> 2.2926126e-06 | BV5: =+Z5/(2*$U5) -> 0.00090367146 | BW5: =+AA5/(2*$U5) -> 0.0001088991 | BX5: =+AB5/(2*$U5) -> 2.4072432e-05 | BY5: =+AC5/(2*$U5) -> 0.00014023147 | ... CF5: =+AJ5/(2*$U5) -> 8.7883483e-06
A6: 5-14 | B6: 2617766.7 | C6: 24 | D6: 114 | E6: 9 | F6: 11 | G6: 1 | H6: 203 | I6: 8 | J6: 37 | K6: 60 | L6: 38 | M6: 10 | N6: 16 | O6: 0 | P6: 27 | Q6: 11 | S6: =+$B$1 -> 1996 | T6: =+A6 -> 5-14 | U6: =+B6 -> 2617766.7 | V6: =+C6 -> 24 | W6: =+D6 -> 114 | X6: =+E6 -> 9 | Y6: =+F6 -> 11 | Z6: =+G6 -> 1 | AA6: =+H6 -> 203 | ... AJ6: =+Q6 -> 11 | AK6: =+SUM(V6:AJ6) -> 569 | AL6: =+V6/$U6 -> 9.1681201e-06 | AM6: =+W6/$U6 -> 4.3548571e-05 | AN6: =+X6/$U6 -> 3.438045e-06 | AO6: =+Y6/$U6 -> 4.2020551e-06 | AP6: =+Z6/$U6 -> 3.8200501e-07 | AQ6: =+AA6/$U6 -> 7.7547016e-05 | AR6: =+AB6/$U6 -> 3.05604e-06 | AS6: =+AC6/$U6 -> 1.4134185e-05 | ... AZ6: =+AJ6/$U6 -> 4.2020551e-06 | BA6: =+AK6/U6 -> 0.00021736085 | BB6: =+U6-(0.5*AK6) -> 2617482.2 | BC6: =+AL6/(1-(0.5*$BA6)) -> 9.1691166e-06 | BD6: =+AM6/(1-(0.5*$BA6)) -> 4.3553304e-05 | BE6: =+AN6/(1-(0.5*$BA6)) -> 3.4384187e-06 | BF6: =+AO6/(1-(0.5*$BA6)) -> 4.2025118e-06 | BG6: =+AP6/(1-(0.5*$BA6)) -> 3.8204653e-07 | BH6: =+AQ6/(1-(0.5*$BA6)) -> 7.7555445e-05 | BI6: =+AR6/(1-(0.5*$BA6)) -> 3.0563722e-06 | BJ6: =+AS6/(1-(0.5*$BA6)) -> 1.4135721e-05 | ... BQ6: =+AZ6/(1-(0.5*$BA6)) -> 4.2025118e-06 | BR6: =+(V5+V6)/(2*$U6) -> 1.1842155e-05 | BS6: =+(W5+W6)/(2*$U6) -> 3.361644e-05 | BT6: =+(X5+X6)/(2*$U6) -> 2.8650375e-06 | BU6: =+(Y5+Y6)/(2*$U6) -> 3.2470425e-06 | BV6: =+(Z5+Z6)/(2*$U6) -> 0.00045191192 | BW6: =+(AA5+AA6)/(2*$U6) -> 9.3209221e-05 | BX6: =+(AB5+AB6)/(2*$U6) -> 1.3561178e-05 | BY6: =+(AC5+AC6)/(2*$U6) -> 7.7165011e-05 | ... CF6: =+(AJ5+AJ6)/(2*$U6) -> 6.4940851e-06
A7: 15-24 | B7: 2136825.7 | C7: 40 | D7: 130 | E7: 28 | F7: 34 | G7: 0 | H7: 267 | I7: 17 | J7: 34 | K7: 28 | L7: 13 | M7: 33 | N7: 11 | O7: 2 | P7: 137 | Q7: 16 | S7: =+$B$1 -> 1996 | T7: =+A7 -> 15-24 | U7: =+B7 -> 2136825.7 | V7: =+C7 -> 40 | W7: =+D7 -> 130 | X7: =+E7 -> 28 | Y7: =+F7 -> 34 | Z7: =+G7 -> 0 | AA7: =+H7 -> 267 | ... AJ7: =+Q7 -> 16 | AK7: =+SUM(V7:AJ7) -> 790 | AL7: =+V7/$U7 -> 1.8719356e-05 | AM7: =+W7/$U7 -> 6.0837906e-05 | AN7: =+X7/$U7 -> 1.3103549e-05 | AO7: =+Y7/$U7 -> 1.5911452e-05 | AP7: =+Z7/$U7 -> 0 | AQ7: =+AA7/$U7 -> 0.0001249517 | AR7: =+AB7/$U7 -> 7.9557262e-06 | AS7: =+AC7/$U7 -> 1.5911452e-05 | ... AZ7: =+AJ7/$U7 -> 7.4877423e-06 | BA7: =+AK7/U7 -> 0.00036970727 | BB7: =+U7-(0.5*AK7) -> 2136430.7 | BC7: =+AL7/(1-(0.5*$BA7)) -> 1.8722817e-05 | BD7: =+AM7/(1-(0.5*$BA7)) -> 6.0849154e-05 | BE7: =+AN7/(1-(0.5*$BA7)) -> 1.3105972e-05 | BF7: =+AO7/(1-(0.5*$BA7)) -> 1.5914394e-05 | BG7: =+AP7/(1-(0.5*$BA7)) -> 0 | BH7: =+AQ7/(1-(0.5*$BA7)) -> 0.0001249748 | BI7: =+AR7/(1-(0.5*$BA7)) -> 7.9571971e-06 | BJ7: =+AS7/(1-(0.5*$BA7)) -> 1.5914394e-05 | ... BQ7: =+AZ7/(1-(0.5*$BA7)) -> 7.4891267e-06 | BR7: =+(V6+V7)/(2*$U7) -> 1.4975485e-05 | BS7: =+(W6+W7)/(2*$U7) -> 5.7094035e-05 | BT7: =+(X6+X7)/(2*$U7) -> 8.657702e-06 | BU7: =+(Y6+Y7)/(2*$U7) -> 1.0529638e-05 | BV7: =+(Z6+Z7)/(2*$U7) -> 2.3399195e-07 | BW7: =+(AA6+AA7)/(2*$U7) -> 0.00010997621 | BX7: =+(AB6+AB7)/(2*$U7) -> 5.8497986e-06 | BY7: =+(AC6+AC7)/(2*$U7) -> 1.6613428e-05 | ... CF7: =+(AJ6+AJ7)/(2*$U7) -> 6.3177825e-06
A8: 25-44 | B8: 3245545.3 | C8: 467 | D8: 1119 | E8: 261 | F8: 113 | G8: 1 | H8: 352 | I8: 50 | J8: 67 | K8: 46 | L8: 29 | M8: 106 | N8: 42 | O8: 24 | P8: 151 | Q8: 54 | S8: =+$B$1 -> 1996 | T8: =+A8 -> 25-44 | U8: =+B8 -> 3245545.3 | V8: =+C8 -> 467 | W8: =+D8 -> 1119 | X8: =+E8 -> 261 | Y8: =+F8 -> 113 | Z8: =+G8 -> 1 | AA8: =+H8 -> 352 | ... AJ8: =+Q8 -> 54 | AK8: =+SUM(V8:AJ8) -> 2882 | AL8: =+V8/$U8 -> 0.00014388953 | AM8: =+W8/$U8 -> 0.00034478028 | AN8: =+X8/$U8 -> 8.041792e-05 | AO8: =+Y8/$U8 -> 3.4816954e-05 | AP8: =+Z8/$U8 -> 3.0811463e-07 | AQ8: =+AA8/$U8 -> 0.00010845635 | AR8: =+AB8/$U8 -> 1.5405732e-05 | AS8: =+AC8/$U8 -> 2.0643681e-05 | ... AZ8: =+AJ8/$U8 -> 1.663819e-05 | BA8: =+AK8/U8 -> 0.00088798638 | BB8: =+U8-(0.5*AK8) -> 3244104.3 | BC8: =+AL8/(1-(0.5*$BA8)) -> 0.00014395345 | BD8: =+AM8/(1-(0.5*$BA8)) -> 0.00034493342 | BE8: =+AN8/(1-(0.5*$BA8)) -> 8.045364e-05 | BF8: =+AO8/(1-(0.5*$BA8)) -> 3.4832419e-05 | BG8: =+AP8/(1-(0.5*$BA8)) -> 3.082515e-07 | BH8: =+AQ8/(1-(0.5*$BA8)) -> 0.00010850453 | BI8: =+AR8/(1-(0.5*$BA8)) -> 1.5412575e-05 | BJ8: =+AS8/(1-(0.5*$BA8)) -> 2.065285e-05 | ... BQ8: =+AZ8/(1-(0.5*$BA8)) -> 1.6645581e-05 | BR8: =+(V7+V8)/(2*$U8) -> 7.810706e-05 | BS8: =+(W7+W8)/(2*$U8) -> 0.00019241759 | BT8: =+(X7+X8)/(2*$U8) -> 4.4522565e-05 | BU8: =+(Y7+Y8)/(2*$U8) -> 2.2646426e-05 | BV8: =+(Z7+Z8)/(2*$U8) -> 1.5405732e-07 | BW8: =+(AA7+AA8)/(2*$U8) -> 9.5361479e-05 | BX8: =+(AB7+AB8)/(2*$U8) -> 1.032184e-05 | BY8: =+(AC7+AC8)/(2*$U8) -> 1.5559789e-05 | ... CF8: =+(AJ7+AJ8)/(2*$U8) -> 1.0784012e-05
A9: 45-64 | B9: 1448878 | C9: 1724 | D9: 2420 | E9: 792 | F9: 689 | G9: 0 | H9: 165 | I9: 194 | J9: 78 | K9: 18 | L9: 75 | M9: 145 | N9: 103 | O9: 81 | P9: 45 | Q9: 142 | S9: =+$B$1 -> 1996 | T9: =+A9 -> 45-64 | U9: =+B9 -> 1448878 | V9: =+C9 -> 1724 | W9: =+D9 -> 2420 | X9: =+E9 -> 792 | Y9: =+F9 -> 689 | Z9: =+G9 -> 0 | AA9: =+H9 -> 165 | ... AJ9: =+Q9 -> 142 | AK9: =+SUM(V9:AJ9) -> 6671 | AL9: =+V9/$U9 -> 0.0011898863 | AM9: =+W9/$U9 -> 0.001670258 | AN9: =+X9/$U9 -> 0.00054662989 | AO9: =+Y9/$U9 -> 0.0004755404 | AP9: =+Z9/$U9 -> 0 | AQ9: =+AA9/$U9 -> 0.00011388123 | AR9: =+AB9/$U9 -> 0.00013389672 | AS9: =+AC9/$U9 -> 5.3834762e-05 | ... AZ9: =+AJ9/$U9 -> 9.8006874e-05 | BA9: =+AK9/U9 -> 0.0046042525 | BB9: =+U9-(0.5*AK9) -> 1445542.5 | BC9: =+AL9/(1-(0.5*$BA9)) -> 0.0011926319 | BD9: =+AM9/(1-(0.5*$BA9)) -> 0.001674112 | BE9: =+AN9/(1-(0.5*$BA9)) -> 0.00054789121 | BF9: =+AO9/(1-(0.5*$BA9)) -> 0.00047663768 | BG9: =+AP9/(1-(0.5*$BA9)) -> 0 | BH9: =+AQ9/(1-(0.5*$BA9)) -> 0.000114144 | BI9: =+AR9/(1-(0.5*$BA9)) -> 0.00013420567 | BJ9: =+AS9/(1-(0.5*$BA9)) -> 5.3958982e-05 | ... BQ9: =+AZ9/(1-(0.5*$BA9)) -> 9.8233019e-05 | BR9: =+(V8+V9)/(2*$U9) -> 0.00075610233 | BS9: =+(W8+W9)/(2*$U9) -> 0.0012212899 | BT9: =+(X8+X9)/(2*$U9) -> 0.00036338464 | BU9: =+(Y8+Y9)/(2*$U9) -> 0.00027676589 | BV9: =+(Z8+Z9)/(2*$U9) -> 3.4509463e-07 | BW9: =+(AA8+AA9)/(2*$U9) -> 0.00017841392 | BX9: =+(AB8+AB9)/(2*$U9) -> 8.4203089e-05 | BY9: =+(AC8+AC9)/(2*$U9) -> 5.0038721e-05 | ... CF9: =+(AJ8+AJ9)/(2*$U9) -> 6.7638547e-05
A10: 65-74 | B10: 373487.34 | C10: 2053 | D10: 1478 | E10: 820 | F10: 707 | G10: 0 | H10: 94 | I10: 233 | J10: 106 | K10: 8 | L10: 63 | M10: 125 | N10: 78 | O10: 97 | P10: 16 | Q10: 124 | S10: =+$B$1 -> 1996 | T10: =+A10 -> 65-74 | U10: =+B10 -> 373487.34 | V10: =+C10 -> 2053 | W10: =+D10 -> 1478 | X10: =+E10 -> 820 | Y10: =+F10 -> 707 | Z10: =+G10 -> 0 | AA10: =+H10 -> 94 | ... AJ10: =+Q10 -> 124 | AK10: =+SUM(V10:AJ10) -> 6002 | AL10: =+V10/$U10 -> 0.0054968396 | AM10: =+W10/$U10 -> 0.0039572961 | AN10: =+X10/$U10 -> 0.0021955229 | AO10: =+Y10/$U10 -> 0.0018929691 | AP10: =+Z10/$U10 -> 0 | AQ10: =+AA10/$U10 -> 0.00025168189 | AR10: =+AB10/$U10 -> 0.00062384979 | AS10: =+AC10/$U10 -> 0.00028381149 | ... AZ10: =+AJ10/$U10 -> 0.0003320059 | BA10: =+AK10/U10 -> 0.016070156 | BB10: =+U10-(0.5*AK10) -> 370486.34 | BC10: =+AL10/(1-(0.5*$BA10)) -> 0.0055413649 | BD10: =+AM10/(1-(0.5*$BA10)) -> 0.0039893509 | BE10: =+AN10/(1-(0.5*$BA10)) -> 0.002213307 | BF10: =+AO10/(1-(0.5*$BA10)) -> 0.0019083025 | BG10: =+AP10/(1-(0.5*$BA10)) -> 0 | BH10: =+AQ10/(1-(0.5*$BA10)) -> 0.00025372055 | BI10: =+AR10/(1-(0.5*$BA10)) -> 0.00062890308 | BJ10: =+AS10/(1-(0.5*$BA10)) -> 0.00028611041 | ... BQ10: =+AZ10/(1-(0.5*$BA10)) -> 0.0003346952 | BR10: =+(V9+V10)/(2*$U10) -> 0.0050563963 | BS10: =+(W9+W10)/(2*$U10) -> 0.005218383 | BT10: =+(X9+X10)/(2*$U10) -> 0.0021580383 | BU10: =+(Y9+Y10)/(2*$U10) -> 0.0018688719 | BV10: =+(Z9+Z10)/(2*$U10) -> 0 | BW10: =+(AA9+AA10)/(2*$U10) -> 0.00034673197 | BX10: =+(AB9+AB10)/(2*$U10) -> 0.00057163919 | BY10: =+(AC9+AC10)/(2*$U10) -> 0.00024632696 | ... CF10: =+(AJ9+AJ10)/(2*$U10) -> 0.0003561031
A11: 75+ | B11: 186458.59 | C11: 5003 | D11: 1582 | E11: 1961 | F11: 819 | G11: 6 | H11: 249 | I11: 555 | J11: 552 | K11: 12 | L11: 226 | M11: 182 | N11: 96 | O11: 188 | P11: 12 | Q11: 112 | S11: =+$B$1 -> 1996 | T11: =+A11 -> 75+ | U11: =+B11 -> 186458.59 | V11: =+C11 -> 5003 | W11: =+D11 -> 1582 | X11: =+E11 -> 1961 | Y11: =+F11 -> 819 | Z11: =+G11 -> 6 | AA11: =+H11 -> 249 | ... AJ11: =+Q11 -> 112 | AK11: =+SUM(V11:AJ11) -> 11555 | AL11: =+V11/$U11 -> 0.026831696 | AM11: =+W11/$U11 -> 0.0084844578 | AN11: =+X11/$U11 -> 0.010517081 | AO11: =+Y11/$U11 -> 0.0043923963 | AP11: =+Z11/$U11 -> 3.2178727e-05 | AQ11: =+AA11/$U11 -> 0.0013354172 | AR11: =+AB11/$U11 -> 0.0029765323 | AS11: =+AC11/$U11 -> 0.0029604429 | ... AZ11: =+AJ11/$U11 -> 0.00060066958 | BA11: =+AK11/U11 -> 0.061970866 | BB11: =+U11-(0.5*AK11) -> 180681.09 | BC11: =+AL11/(1-(0.5*$BA11)) -> 0.027689672 | BD11: =+AM11/(1-(0.5*$BA11)) -> 0.0087557588 | BE11: =+AN11/(1-(0.5*$BA11)) -> 0.010853377 | BF11: =+AO11/(1-(0.5*$BA11)) -> 0.0045328486 | BG11: =+AP11/(1-(0.5*$BA11)) -> 3.3207682e-05 | BH11: =+AQ11/(1-(0.5*$BA11)) -> 0.0013781188 | BI11: =+AR11/(1-(0.5*$BA11)) -> 0.0030717106 | BJ11: =+AS11/(1-(0.5*$BA11)) -> 0.0030551067 | ... BQ11: =+AZ11/(1-(0.5*$BA11)) -> 0.00061987673 | BR11: =+(V10+V11)/(2*$U11) -> 0.018921092 | BS11: =+(W10+W11)/(2*$U11) -> 0.0082055755 | BT11: =+(X10+X11)/(2*$U11) -> 0.0074574201 | BU11: =+(Y10+Y11)/(2*$U11) -> 0.0040920615 | BV11: =+(Z10+Z11)/(2*$U11) -> 1.6089364e-05 | BW11: =+(AA10+AA11)/(2*$U11) -> 0.00091977529 | BX11: =+(AB10+AB11)/(2*$U11) -> 0.0021130698 | BY11: =+(AC10+AC11)/(2*$U11) -> 0.0017644669 | ... CF11: =+(AJ10+AJ11)/(2*$U11) -> 0.00063284831
S14: Leyenda
S15: Posicion | T15: Causa
S16: 1 | T16: Enfermedades del Corazón (I05-I09, I11, I13, I21-I51)
S17: 2 | T17: Cancer (C00-C97)
S18: 3 | T18: Enfermedad Cerebrovascular (I60-I69)
S19: 4 | T19: Diabetes (E10-E14)
S20: 5 | T20: Ciertas afecciones originadas en el período perinatal (P00-P96)
S21: 6 | T21: Accidentes de Todo Tipo (V01-X59)
S22: 7 | T22: Enfermedades crónicas de las vías respiratorias inferiores (J40-J47)
S23: 8 | T23: Influenza y neumonía (J09-J18)
S24: 9 | T24: Malformaciones congénitas, deformidades y anomalías cromosómicas (Q00-Q99)
S25: 10 | T25: Enfermedades infecciosas intestinales(A00-A09)
S26: 11 | T26: Nefritis y Nefrosis (N00-N19, N25-N29)
S27: 12 | T27: Tumores benignos y de comportamiento incierto o desconocido (D10-D48)
S28: 13 | T28: Otras enfermedades Hipertensivas (I10-I12)
S29: 14 | T29: Suicidios y Homicidios. (X60-Y09)
S30: 15 | T30: Enfermedades del hígado. (K70-K77)

Sheet TDM_Total
A3: Año | B3: 1996 | E3: Tabla de Decrecimiento Multiple Todas las Causas | O3: 100000
F4: Poblacion General
B5: Valores | L5: Tasa Central de Decrecimiento | M5: Tasa Intantanea de Decrecimiento
A6: Grupo Etario | B6: Máx. de Población | C6: Suma de Fallecimientos | E6: Año | F6: Grupo Etario | G6: lx(T) | H6: dx(T) | I6: qx(T) | J6: Px(T) | K6: Lx(T) | L6: mx(T) | M6: µ(X) | N6: Proporcion del Grupo Etario Vs Poblacion Total | O6: Poblacion en base a 100.000 Personas | P6: Poblacion Estimada | Q6: Fallecimientos Totales
A7: 0-4 | B7: 2669011.1 | C7: 11844 | E7: =+$B$3 -> 1996 | F7: =+A7 -> 0-4 | G7: =+B7 -> 2669011.1 | H7: =+C7 -> 11844 | I7: =+H7/G7 -> 0.0044375987 | J7: =1-I7 -> 0.9955624 | K7: =+G7-(0.5*H7) -> 2663089.1 | L7: =+H7/K7 -> 0.0044474667 | M7: =+H7/(2*G7) -> 0.0022187993 | N7: =+G7/$G$14 -> 0.11545451 | O7: =+N7*$O$3 -> 11545.451 | P7: 100000 | Q7: =+P7*I7 -> 443.75987
A8: 5-14 | B8: 5336689.3 | C8: 1485 | E8: =+$B$3 -> 1996 | F8: =+A8 -> 5-14 | G8: =+B8 -> 5336689.3 | H8: =+C8 -> 1485 | I8: =+H8/G8 -> 0.00027826241 | J8: =1-I8 -> 0.99972174 | K8: =+G8-(0.5*H8) -> 5335946.8 | L8: =+H8/K8 -> 0.00027830113 | M8: =+(H7+H8)/(2*G8) -> 0.001248808 | N8: =+G8/$G$14 -> 0.23085137 | O8: =+N8*$O$3 -> 23085.137 | P8: =+P7-Q7 -> 99556.24 | Q8: =+P8*I8 -> 27.702759
A9: 15-24 | B9: 4328734.7 | C9: 3967 | E9: =+$B$3 -> 1996 | F9: =+A9 -> 15-24 | G9: =+B9 -> 4328734.7 | H9: =+C9 -> 3967 | I9: =+H9/G9 -> 0.00091643407 | J9: =1-I9 -> 0.99908357 | K9: =+G9-(0.5*H9) -> 4326751.2 | L9: =+H9/K9 -> 0.00091685419 | M9: =+(H8+H9)/(2*G9) -> 0.00062974522 | N9: =+G9/$G$14 -> 0.18724987 | O9: =+N9*$O$3 -> 18724.987 | P9: =+P8-Q8 -> 99528.537 | Q9: =+P9*I9 -> 91.211343
A10: 25-44 | B10: 6500086.9 | C10: 9771 | E10: =+$B$3 -> 1996 | F10: =+A10 -> 25-44 | G10: =+B10 -> 6500086.9 | H10: =+C10 -> 9771 | I10: =+H10/G10 -> 0.0015032107 | J10: =1-I10 -> 0.99849679 | K10: =+G10-(0.5*H10) -> 6495201.4 | L10: =+H10/K10 -> 0.0015043413 | M10: =+(H9+H10)/(2*G10) -> 0.0010567551 | N10: =+G10/$G$14 -> 0.28117694 | O10: =+N10*$O$3 -> 28117.694 | P10: =+P9-Q9 -> 99437.326 | Q10: =+P10*I10 -> 149.47525
A11: 45-64 | B11: 2862216.5 | C11: 16784 | E11: =+$B$3 -> 1996 | F11: =+A11 -> 45-64 | G11: =+B11 -> 2862216.5 | H11: =+C11 -> 16784 | I11: =+H11/G11 -> 0.0058639869 | J11: =1-I11 -> 0.99413601 | K11: =+G11-(0.5*H11) -> 2853824.5 | L11: =+H11/K11 -> 0.0058812306 | M11: =+(H10+H11)/(2*G11) -> 0.0046388874 | N11: =+G11/$G$14 -> 0.12381208 | O11: =+N11*$O$3 -> 12381.208 | P11: =+P10-Q10 -> 99287.851 | Q11: =+P11*I11 -> 582.22266
A12: 65-74 | B12: 710343.29 | C12: 14038 | E12: =+$B$3 -> 1996 | F12: =+A12 -> 65-74 | G12: =+B12 -> 710343.29 | H12: =+C12 -> 14038 | I12: =+H12/G12 -> 0.019762276 | J12: =1-I12 -> 0.98023772 | K12: =+G12-(0.5*H12) -> 703324.29 | L12: =+H12/K12 -> 0.019959498 | M12: =+(H11+H12)/(2*G12) -> 0.021695144 | N12: =+G12/$G$14 -> 0.030727613 | O12: =+N12*$O$3 -> 3072.7613 | P12: =+P11-Q11 -> 98705.628 | Q12: =+P12*I12 -> 1950.6479
A13: 75+ | B13: 710343.29 | C13: 21624 | E13: =+$B$3 -> 1996 | F13: =+A13 -> 75+ | G13: =+B13 -> 710343.29 | H13: =+C13 -> 21624 | I13: =+H13/G13 -> 0.030441619 | J13: =1-I13 -> 0.96955838 | K13: =+G13-(0.5*H13) -> 699531.29 | L13: =+H13/K13 -> 0.030912127 | M13: =+(H12+H13)/(2*G13) -> 0.025101948 | N13: =+G13/$G$14 -> 0.030727613 | O13: =+N13*$O$3 -> 3072.7613 | P13: =+P12-Q12 -> 96754.98 | Q13: =+P13*I13 -> 2945.3783
B14: =+SUM(B7:B13) -> 23117425 | C14: =+SUM(C7:C13) -> 79513 | E14: Totales | G14: =+SUM(G7:G13) -> 23117425 | H14: =+SUM(H7:H13) -> 79513 | I14: =+H14/G14 -> 0.0034395267
E17: Gráficos
E18: Población Total por cada 100.000 personas | J18: Fallecimientos Totales por cada 100.000 personas
E35: Comparaciones entre Probabilidades, Tasas Centrales y Tasas Instantáneas, por cualquier causa de decrecimiento | J35: Población y Probabilidad de Decrecimiento Total, por cualquier causa de decrecimiento
M36: Probabilidad de Decrecimiento por Cualquier causa

Sheet TDM_Total_Causa
A1: Año | B1: 1996 | T1: Tabla de Decrecimiento Multiple
T2: Poblacion General
A3: Suma de Fallecimientos | C3: Posicion
A4: Grupo Etario | B4: Población | C4: 1 | D4: 2 | E4: 3 | F4: 4 | G4: 5 | H4: 6 | I4: 7 | J4: 8 | K4: 9 | L4: 10 | M4: 11 | N4: 12 | O4: 13 | P4: 14 | Q4: 15 | S4: Año | T4: Grupo Etario | U4: lx(T) | V4: =+CONCATENATE("dx","(",C4,")") -> dx(1) | W4: =+CONCATENATE("dx","(",D4,")") -> dx(2) | X4: =+CONCATENATE("dx","(",E4,")") -> dx(3) | Y4: =+CONCATENATE("dx","(",F4,")") -> dx(4) | Z4: =+CONCATENATE("dx","(",G4,")") -> dx(5) | AA4: =+CONCATENATE("dx","(",H4,")") -> dx(6) | AB4: =+CONCATENATE("dx","(",I4,")") -> dx(7) | AC4: =+CONCATENATE("dx","(",J4,")") -> dx(8) | ... AJ4: =+CONCATENATE("dx","(",Q4,")") -> dx(15) | AK4: dx(T) | AL4: =+CONCATENATE("qx","(",C4,")") -> qx(1) | AM4: =+CONCATENATE("qx","(",D4,")") -> qx(2) | AN4: =+CONCATENATE("qx","(",E4,")") -> qx(3) | AO4: =+CONCATENATE("qx","(",F4,")") -> qx(4) | AP4: =+CONCATENATE("qx","(",G4,")") -> qx(5) | AQ4: =+CONCATENATE("qx","(",H4,")") -> qx(6) | AR4: =+CONCATENATE("qx","(",I4,")") -> qx(7) | AS4: =+CONCATENATE("qx","(",J4,")") -> qx(8) | ... AZ4: =+CONCATENATE("qx","(",Q4,")") -> qx(15) | BA4: =+CONCATENATE("qx","(T)") -> qx(T) | BB4: Lx(T) | BC4: =+CONCATENATE("mx","(",C4,")") -> mx(1) | BD4: =+CONCATENATE("mx","(",D4,")") -> mx(2) | BE4: =+CONCATENATE("mx","(",E4,")") -> mx(3) | BF4: =+CONCATENATE("mx","(",F4,")") -> mx(4) | BG4: =+CONCATENATE("mx","(",G4,")") -> mx(5) | BH4: =+CONCATENATE("mx","(",H4,")") -> mx(6) | BI4: =+CONCATENATE("mx","(",I4,")") -> mx(7) | BJ4: =+CONCATENATE("mx","(",J4,")") -> mx(8) | ... BQ4: =+CONCATENATE("mx","(",Q4,")") -> mx(15) | BR4: =+CONCATENATE("µ(X)",C4) -> µ(X)1 | BS4: =+CONCATENATE("µ(X)",D4) -> µ(X)2 | BT4: =+CONCATENATE("µ(X)",E4) -> µ(X)3 | BU4: =+CONCATENATE("µ(X)",F4) -> µ(X)4 | BV4: =+CONCATENATE("µ(X)",G4) -> µ(X)5 | BW4: =+CONCATENATE("µ(X)",H4) -> µ(X)6 | BX4: =+CONCATENATE("µ(X)",I4) -> µ(X)7 | BY4: =+CONCATENATE("µ(X)",J4) -> µ(X)8 | ... CF4: =+CONCATENATE("µ(X)",Q4) -> µ(X)15
A5: 0-4 | B5: 2669011.1 | C5: 82 | D5: 159 | E5: 14 | F5: 786 | G5: 32 | H5: 12 | I5: 5626 | J5: 114 | K5: 877 | L5: 35 | M5: 1552 | N5: 2468 | O5: 37 | P5: 21 | Q5: 29 | S5: =+$B$1 -> 1996 | T5: =+A5 -> 0-4 | U5: =+B5 -> 2669011.1 | V5: =+C5 -> 82 | W5: =+D5 -> 159 | X5: =+E5 -> 14 | Y5: =+F5 -> 786 | Z5: =+G5 -> 32 | AA5: =+H5 -> 12 | ... AJ5: =+Q5 -> 29 | AK5: =+SUM(V5:AJ5) -> 11844 | AL5: =+V5/$U5 -> 3.072299e-05 | AM5: =+W5/$U5 -> 5.9572627e-05 | AN5: =+X5/$U5 -> 5.2453885e-06 | AO5: =+Y5/$U5 -> 0.0002944911 | AP5: =+Z5/$U5 -> 1.1989459e-05 | AQ5: =+AA5/$U5 -> 4.4960473e-06 | AR5: =+AB5/$U5 -> 0.0021078968 | AS5: =+AC5/$U5 -> 4.2712449e-05 | ... AZ5: =+AJ5/$U5 -> 1.0865448e-05 | BA5: =+AK5/U5 -> 0.0044375987 | BB5: =+U5-(0.5*AK5) -> 2663089.1 | BC5: =+AL5/(1-(0.5*$BA5)) -> 3.079131e-05 | BD5: =+AM5/(1-(0.5*$BA5)) -> 5.97051e-05 | BE5: =+AN5/(1-(0.5*$BA5)) -> 5.2570529e-06 | BF5: =+AO5/(1-(0.5*$BA5)) -> 0.00029514597 | BG5: =+AP5/(1-(0.5*$BA5)) -> 1.2016121e-05 | BH5: =+AQ5/(1-(0.5*$BA5)) -> 4.5060453e-06 | BI5: =+AR5/(1-(0.5*$BA5)) -> 0.0021125842 | BJ5: =+AS5/(1-(0.5*$BA5)) -> 4.280743e-05 | ... BQ5: =+AZ5/(1-(0.5*$BA5)) -> 1.088961e-05 | BR5: =+V5/(2*$U5) -> 1.5361495e-05 | BS5: =+W5/(2*$U5) -> 2.9786313e-05 | BT5: =+X5/(2*$U5) -> 2.6226943e-06 | BU5: =+Y5/(2*$U5) -> 0.00014724555 | BV5: =+Z5/(2*$U5) -> 5.9947297e-06 | BW5: =+AA5/(2*$U5) -> 2.2480237e-06 | BX5: =+AB5/(2*$U5) -> 0.0010539484 | BY5: =+AC5/(2*$U5) -> 2.1356225e-05 | ... CF5: =+AJ5/(2*$U5) -> 5.4327238e-06
A6: 5-14 | B6: 5336689.3 | C6: 50 | D6: 266 | E6: 18 | F6: 659 | G6: 105 | H6: 16 | I6: 2 | J6: 15 | K6: 82 | L6: 18 | M6: 121 | N6: 79 | O6: 18 | P6: 2 | Q6: 34 | S6: =+$B$1 -> 1996 | T6: =+A6 -> 5-14 | U6: =+B6 -> 5336689.3 | V6: =+C6 -> 50 | W6: =+D6 -> 266 | X6: =+E6 -> 18 | Y6: =+F6 -> 659 | Z6: =+G6 -> 105 | AA6: =+H6 -> 16 | ... AJ6: =+Q6 -> 34 | AK6: =+SUM(V6:AJ6) -> 1485 | AL6: =+V6/$U6 -> 9.3691046e-06 | AM6: =+W6/$U6 -> 4.9843637e-05 | AN6: =+X6/$U6 -> 3.3728777e-06 | AO6: =+Y6/$U6 -> 0.0001234848 | AP6: =+Z6/$U6 -> 1.967512e-05 | AQ6: =+AA6/$U6 -> 2.9981135e-06 | AR6: =+AB6/$U6 -> 3.7476418e-07 | AS6: =+AC6/$U6 -> 2.8107314e-06 | ... AZ6: =+AJ6/$U6 -> 6.3709911e-06 | BA6: =+AK6/U6 -> 0.00027826241 | BB6: =+U6-(0.5*AK6) -> 5335946.8 | BC6: =+AL6/(1-(0.5*$BA6)) -> 9.3704083e-06 | BD6: =+AM6/(1-(0.5*$BA6)) -> 4.9850572e-05 | BE6: =+AN6/(1-(0.5*$BA6)) -> 3.373347e-06 | BF6: =+AO6/(1-(0.5*$BA6)) -> 0.00012350198 | BG6: =+AP6/(1-(0.5*$BA6)) -> 1.9677857e-05 | BH6: =+AQ6/(1-(0.5*$BA6)) -> 2.9985307e-06 | BI6: =+AR6/(1-(0.5*$BA6)) -> 3.7481633e-07 | BJ6: =+AS6/(1-(0.5*$BA6)) -> 2.8111225e-06 | ... BQ6: =+AZ6/(1-(0.5*$BA6)) -> 6.3718777e-06 | BR6: =+(V5+V6)/(2*$U6) -> 1.2367218e-05 | BS6: =+(W5+W6)/(2*$U6) -> 3.9818695e-05 | BT6: =+(X5+X6)/(2*$U6) -> 2.9981135e-06 | BU6: =+(Y5+Y6)/(2*$U6) -> 0.00013538356 | BV6: =+(Z5+Z6)/(2*$U6) -> 1.2835673e-05 | BW6: =+(AA5+AA6)/(2*$U6) -> 2.6233493e-06 | BX6: =+(AB5+AB6)/(2*$U6) -> 0.00052729321 | BY6: =+(AC5+AC6)/(2*$U6) -> 1.2086145e-05 | ... CF6: =+(AJ5+AJ6)/(2*$U6) -> 5.9025359e-06
A7: 15-24 | B7: 4328734.7 | C7: 101 | D7: 301 | E7: 64 | F7: 1352 | G7: 1694 | H7: 51 | I7: 0 | J7: 33 | K7: 90 | L7: 34 | M7: 66 | N7: 36 | O7: 71 | P7: 47 | Q7: 27 | S7: =+$B$1 -> 1996 | T7: =+A7 -> 15-24 | U7: =+B7 -> 4328734.7 | V7: =+C7 -> 101 | W7: =+D7 -> 301 | X7: =+E7 -> 64 | Y7: =+F7 -> 1352 | Z7: =+G7 -> 1694 | AA7: =+H7 -> 51 | ... AJ7: =+Q7 -> 27 | AK7: =+SUM(V7:AJ7) -> 3967 | AL7: =+V7/$U7 -> 2.3332453e-05 | AM7: =+W7/$U7 -> 6.953533e-05 | AN7: =+X7/$U7 -> 1.4784921e-05 | AO7: =+Y7/$U7 -> 0.00031233145 | AP7: =+Z7/$U7 -> 0.00039133837 | AQ7: =+AA7/$U7 -> 1.1781734e-05 | AR7: =+AB7/$U7 -> 0 | AS7: =+AC7/$U7 -> 7.6234748e-06 | ... AZ7: =+AJ7/$U7 -> 6.2373884e-06 | BA7: =+AK7/U7 -> 0.00091643407 | BB7: =+U7-(0.5*AK7) -> 4326751.2 | BC7: =+AL7/(1-(0.5*$BA7)) -> 2.3343149e-05 | BD7: =+AM7/(1-(0.5*$BA7)) -> 6.9567207e-05 | BE7: =+AN7/(1-(0.5*$BA7)) -> 1.4791699e-05 | BF7: =+AO7/(1-(0.5*$BA7)) -> 0.00031247463 | BG7: =+AP7/(1-(0.5*$BA7)) -> 0.00039151777 | BH7: =+AQ7/(1-(0.5*$BA7)) -> 1.1787135e-05 | BI7: =+AR7/(1-(0.5*$BA7)) -> 0 | BJ7: =+AS7/(1-(0.5*$BA7)) -> 7.6269696e-06 | ... BQ7: =+AZ7/(1-(0.5*$BA7)) -> 6.2402478e-06 | BR7: =+(V6+V7)/(2*$U7) -> 1.7441586e-05 | BS7: =+(W6+W7)/(2*$U7) -> 6.5492579e-05 | BT7: =+(X6+X7)/(2*$U7) -> 9.4715899e-06 | BU7: =+(Y6+Y7)/(2*$U7) -> 0.00023228497 | BV7: =+(Z6+Z7)/(2*$U7) -> 0.00020779744 | BW7: =+(AA6+AA7)/(2*$U7) -> 7.738982e-06 | BX7: =+(AB6+AB7)/(2*$U7) -> 2.3101439e-07 | BY7: =+(AC6+AC7)/(2*$U7) -> 5.5443453e-06 | ... CF7: =+(AJ6+AJ7)/(2*$U7) -> 7.0459388e-06
A8: 25-44 | B8: 6500086.9 | C8: 1265 | D8: 1734 | E8: 517 | F8: 2393 | G8: 1811 | H8: 272 | I8: 1 | J8: 99 | K8: 191 | L8: 267 | M8: 94 | N8: 65 | O8: 232 | P8: 719 | Q8: 111 | S8: =+$B$1 -> 1996 | T8: =+A8 -> 25-44 | U8: =+B8 -> 6500086.9 | V8: =+C8 -> 1265 | W8: =+D8 -> 1734 | X8: =+E8 -> 517 | Y8: =+F8 -> 2393 | Z8: =+G8 -> 1811 | AA8: =+H8 -> 272 | ... AJ8: =+Q8 -> 111 | AK8: =+SUM(V8:AJ8) -> 9771 | AL8: =+V8/$U8 -> 0.00019461278 | AM8: =+W8/$U8 -> 0.00026676566 | AN8: =+X8/$U8 -> 7.9537398e-05 | AO8: =+Y8/$U8 -> 0.00036814892 | AP8: =+Z8/$U8 -> 0.00027861166 | AQ8: =+AA8/$U8 -> 4.1845594e-05 | AR8: =+AB8/$U8 -> 1.538441e-07 | AS8: =+AC8/$U8 -> 1.5230566e-05 | ... AZ8: =+AJ8/$U8 -> 1.7076695e-05 | BA8: =+AK8/U8 -> 0.0015032107 | BB8: =+U8-(0.5*AK8) -> 6495201.4 | BC8: =+AL8/(1-(0.5*$BA8)) -> 0.00019475916 | BD8: =+AM8/(1-(0.5*$BA8)) -> 0.00026696632 | BE8: =+AN8/(1-(0.5*$BA8)) -> 7.9597223e-05 | BF8: =+AO8/(1-(0.5*$BA8)) -> 0.00036842583 | BG8: =+AP8/(1-(0.5*$BA8)) -> 0.00027882122 | BH8: =+AQ8/(1-(0.5*$BA8)) -> 4.1877069e-05 | BI8: =+AR8/(1-(0.5*$BA8)) -> 1.5395981e-07 | BJ8: =+AS8/(1-(0.5*$BA8)) -> 1.5242022e-05 | ... BQ8: =+AZ8/(1-(0.5*$BA8)) -> 1.7089539e-05 | BR8: =+(V7+V8)/(2*$U8) -> 0.00010507552 | BS8: =+(W7+W8)/(2*$U8) -> 0.00015653637 | BT8: =+(X7+X8)/(2*$U8) -> 4.469171e-05 | BU8: =+(Y7+Y8)/(2*$U8) -> 0.00028807307 | BV8: =+(Z7+Z8)/(2*$U8) -> 0.00026961178 | BW8: =+(AA7+AA8)/(2*$U8) -> 2.4845822e-05 | BX8: =+(AB7+AB8)/(2*$U8) -> 7.6922048e-08 | BY8: =+(AC7+AC8)/(2*$U8) -> 1.015371e-05 | ... CF8: =+(AJ7+AJ8)/(2*$U8) -> 1.0615243e-05
A9: 45-64 | B9: 2862216.5 | C9: 5170 | D9: 4424 | E9: 1783 | F9: 1078 | G9: 502 | H9: 1450 | I9: 0 | J9: 427 | K9: 247 | L9: 791 | M9: 38 | N9: 151 | O9: 387 | P9: 130 | Q9: 206 | S9: =+$B$1 -> 1996 | T9: =+A9 -> 45-64 | U9: =+B9 -> 2862216.5 | V9: =+C9 -> 5170 | W9: =+D9 -> 4424 | X9: =+E9 -> 1783 | Y9: =+F9 -> 1078 | Z9: =+G9 -> 502 | AA9: =+H9 -> 1450 | ... AJ9: =+Q9 -> 206 | AK9: =+SUM(V9:AJ9) -> 16784 | AL9: =+V9/$U9 -> 0.0018062924 | AM9: =+W9/$U9 -> 0.0015456553 | AN9: =+X9/$U9 -> 0.0006229438 | AO9: =+Y9/$U9 -> 0.00037663119 | AP9: =+Z9/$U9 -> 0.00017538855 | AQ9: =+AA9/$U9 -> 0.00050660039 | AR9: =+AB9/$U9 -> 0 | AS9: =+AC9/$U9 -> 0.00014918508 | ... AZ9: =+AJ9/$U9 -> 7.1972194e-05 | BA9: =+AK9/U9 -> 0.0058639869 | BB9: =+U9-(0.5*AK9) -> 2853824.5 | BC9: =+AL9/(1-(0.5*$BA9)) -> 0.0018116041 | BD9: =+AM9/(1-(0.5*$BA9)) -> 0.0015502004 | BE9: =+AN9/(1-(0.5*$BA9)) -> 0.00062477563 | BF9: =+AO9/(1-(0.5*$BA9)) -> 0.00037773872 | BG9: =+AP9/(1-(0.5*$BA9)) -> 0.0001759043 | BH9: =+AQ9/(1-(0.5*$BA9)) -> 0.00050809011 | BI9: =+AR9/(1-(0.5*$BA9)) -> 0 | BJ9: =+AS9/(1-(0.5*$BA9)) -> 0.00014962378 | ... BQ9: =+AZ9/(1-(0.5*$BA9)) -> 7.2183836e-05 | BR9: =+(V8+V9)/(2*$U9) -> 0.0011241288 | BS9: =+(W8+W9)/(2*$U9) -> 0.0010757397 | BT9: =+(X8+X9)/(2*$U9) -> 0.00040178652 | BU9: =+(Y8+Y9)/(2*$U9) -> 0.00060634827 | BV9: =+(Z8+Z9)/(2*$U9) -> 0.00040405749 | BW9: =+(AA8+AA9)/(2*$U9) -> 0.00030081582 | BX9: =+(AB8+AB9)/(2*$U9) -> 1.7468979e-07 | BY9: =+(AC8+AC9)/(2*$U9) -> 9.188683e-05 | ... CF9: =+(AJ8+AJ9)/(2*$U9) -> 5.5376664e-05
A10: 65-74 | B10: 710343.29 | C10: 5212 | D10: 3335 | E10: 1780 | F10: 380 | G10: 125 | H10: 1343 | I10: 0 | J10: 576 | K10: 226 | L10: 406 | M10: 24 | N10: 146 | O10: 319 | P10: 5 | Q10: 161 | S10: =+$B$1 -> 1996 | T10: =+A10 -> 65-74 | U10: =+B10 -> 710343.29 | V10: =+C10 -> 5212 | W10: =+D10 -> 3335 | X10: =+E10 -> 1780 | Y10: =+F10 -> 380 | Z10: =+G10 -> 125 | AA10: =+H10 -> 1343 | ... AJ10: =+Q10 -> 161 | AK10: =+SUM(V10:AJ10) -> 14038 | AL10: =+V10/$U10 -> 0.0073372975 | AM10: =+W10/$U10 -> 0.0046949131 | AN10: =+X10/$U10 -> 0.0025058307 | AO10: =+Y10/$U10 -> 0.00053495262 | AP10: =+Z10/$U10 -> 0.00017597126 | AQ10: =+AA10/$U10 -> 0.0018906352 | AR10: =+AB10/$U10 -> 0 | AS10: =+AC10/$U10 -> 0.00081087554 | ... AZ10: =+AJ10/$U10 -> 0.00022665098 | BA10: =+AK10/U10 -> 0.019762276 | BB10: =+U10-(0.5*AK10) -> 703324.29 | BC10: =+AL10/(1-(0.5*$BA10)) -> 0.0074105218 | BD10: =+AM10/(1-(0.5*$BA10)) -> 0.0047417671 | BE10: =+AN10/(1-(0.5*$BA10)) -> 0.0025308382 | BF10: =+AO10/(1-(0.5*$BA10)) -> 0.00054029131 | BG10: =+AP10/(1-(0.5*$BA10)) -> 0.0001777274 | BH10: =+AQ10/(1-(0.5*$BA10)) -> 0.0019095032 | BI10: =+AR10/(1-(0.5*$BA10)) -> 0 | BJ10: =+AS10/(1-(0.5*$BA10)) -> 0.00081896788 | ... BQ10: =+AZ10/(1-(0.5*$BA10)) -> 0.0002289129 | BR10: =+(V9+V10)/(2*$U10) -> 0.0073077343 | BS10: =+(W9+W10)/(2*$U10) -> 0.0054614439 | BT10: =+(X9+X10)/(2*$U10) -> 0.0025079423 | BU10: =+(Y9+Y10)/(2*$U10) -> 0.0010262644 | BV10: =+(Z9+Z10)/(2*$U10) -> 0.00044133591 | BW10: =+(AA9+AA10)/(2*$U10) -> 0.0019659509 | BX10: =+(AB9+AB10)/(2*$U10) -> 0 | BY10: =+(AC9+AC10)/(2*$U10) -> 0.00070599668 | ... CF10: =+(AJ9+AJ10)/(2*$U10) -> 0.0002583258
A11: 75+ | B11: 710343.29 | C11: 9429 | D11: 3401 | E11: 3442 | F11: 534 | G11: 68 | H11: 1306 | I11: 14 | J11: 1141 | K11: 974 | L11: 279 | M11: 22 | N11: 432 | O11: 397 | P11: 7 | Q11: 178 | S11: =+$B$1 -> 1996 | T11: =+A11 -> 75+ | U11: =+B11 -> 710343.29 | V11: =+C11 -> 9429 | W11: =+D11 -> 3401 | X11: =+E11 -> 3442 | Y11: =+F11 -> 534 | Z11: =+G11 -> 68 | AA11: =+H11 -> 1306 | ... AJ11: =+Q11 -> 178 | AK11: =+SUM(V11:AJ11) -> 21624 | AL11: =+V11/$U11 -> 0.013273864 | AM11: =+W11/$U11 -> 0.0047878259 | AN11: =+X11/$U11 -> 0.0048455445 | AO11: =+Y11/$U11 -> 0.0007517492 | AP11: =+Z11/$U11 -> 9.5728363e-05 | AQ11: =+AA11/$U11 -> 0.0018385477 | AR11: =+AB11/$U11 -> 1.9708781e-05 | AS11: =+AC11/$U11 -> 0.0016062656 | ... AZ11: =+AJ11/$U11 -> 0.00025058307 | BA11: =+AK11/U11 -> 0.030441619 | BB11: =+U11-(0.5*AK11) -> 699531.29 | BC11: =+AL11/(1-(0.5*$BA11)) -> 0.013479025 | BD11: =+AM11/(1-(0.5*$BA11)) -> 0.0048618269 | BE11: =+AN11/(1-(0.5*$BA11)) -> 0.0049204375 | BF11: =+AO11/(1-(0.5*$BA11)) -> 0.00076336829 | BG11: =+AP11/(1-(0.5*$BA11)) -> 9.7207947e-05 | BH11: =+AQ11/(1-(0.5*$BA11)) -> 0.0018669644 | BI11: =+AR11/(1-(0.5*$BA11)) -> 2.0013401e-05 | BJ11: =+AS11/(1-(0.5*$BA11)) -> 0.0016310922 | ... BQ11: =+AZ11/(1-(0.5*$BA11)) -> 0.0002544561 | BR11: =+(V10+V11)/(2*$U11) -> 0.010305581 | BS11: =+(W10+W11)/(2*$U11) -> 0.0047413695 | BT11: =+(X10+X11)/(2*$U11) -> 0.0036756876 | BU11: =+(Y10+Y11)/(2*$U11) -> 0.00064335091 | BV11: =+(Z10+Z11)/(2*$U11) -> 0.00013584981 | BW11: =+(AA10+AA11)/(2*$U11) -> 0.0018645914 | BX11: =+(AB10+AB11)/(2*$U11) -> 9.8543903e-06 | BY11: =+(AC10+AC11)/(2*$U11) -> 0.0012085706 | ... CF11: =+(AJ10+AJ11)/(2*$U11) -> 0.00023861702
T14: Leyenda
T15: Posicion | U15: Causa
T16: 1 | U16: Enfermedades del Corazón (I05-I09, I11, I13, I21-I51)
T17: 2 | U17: Cancer (C00-C97)
T18: 3 | U18: Enfermedad Cerebrovascular (I60-I69)
T19: 4 | U19: Accidentes de Todo Tipo (V01-X59)
T20: 5 | U20: Suicidios y Homicidios. (X60-Y09)
T21: 6 | U21: Diabetes (E10-E14)
T22: 7 | U22: Ciertas afecciones originadas en el período perinatal (P00-P96)
T23: 8 | U23: Enfermedades crónicas de las vías respiratorias inferiores (J40-J47)
T24: 9 | U24: Influenza y neumonía (J09-J18)
T25: 10 | U25: Enfermedades del hígado. (K70-K77)
T26: 11 | U26: Malformaciones congénitas, deformidades y anomalías cromosómicas (Q00-Q99)
T27: 12 | U27: Enfermedades infecciosas intestinales(A00-A09)
... T30: 15 | U30: Tumores benignos y de comportamiento incierto o desconocido (D10-D48)
A32: Año | B32: 1996
A34: Suma de Fallecimientos | C34: Posicion
A35: Grupo Etario | B35: Población | C35: 1 | D35: 10 | E35: 11 | F35: 12 | G35: 13 | H35: 2 | I35: 3 | J35: 4 | K35: 5 | L35: 6 | M35: 7 | N35: 8 | O35: 9 | P35: 14 | Q35: 15 | S35: Año | T35: Grupo Etario | U35: lx(T) | V35: =+CONCATENATE("dx","(",C35,")") -> dx(1) | W35: =+CONCATENATE("dx","(",D35,")") -> dx(10) | X35: =+CONCATENATE("dx","(",E35,")") -> dx(11) | Y35: =+CONCATENATE("dx","(",F35,")") -> dx(12) | Z35: =+CONCATENATE("dx","(",G35,")") -> dx(13) | AA35: =+CONCATENATE("dx","(",H35,")") -> dx(2) | AB35: =+CONCATENATE("dx","(",I35,")") -> dx(3) | AC35: =+CONCATENATE("dx","(",J35,")") -> dx(4) | ... AJ35: =+CONCATENATE("dx","(",Q35,")") -> dx(15) | AK35: dx(T) | AL35: =+CONCATENATE("qx","(",C35,")") -> qx(1) | AM35: =+CONCATENATE("qx","(",D35,")") -> qx(10) | AN35: =+CONCATENATE("qx","(",E35,")") -> qx(11) | AO35: =+CONCATENATE("qx","(",F35,")") -> qx(12) | AP35: =+CONCATENATE("qx","(",G35,")") -> qx(13) | AQ35: =+CONCATENATE("qx","(",H35,")") -> qx(2) | AR35: =+CONCATENATE("qx","(",I35,")") -> qx(3) | AS35: =+CONCATENATE("qx","(",J35,")") -> qx(4) | ... AZ35: =+CONCATENATE("qx","(",Q35,")") -> qx(15) | BA35: =+CONCATENATE("qx","(T)") -> qx(T) | BB35: Lx(T) | BC35: =+CONCATENATE("mx","(",C35,")") -> mx(1) | BD35: =+CONCATENATE("mx","(",D35,")") -> mx(10) | BE35: =+CONCATENATE("mx","(",E35,")") -> mx(11) | BF35: =+CONCATENATE("mx","(",F35,")") -> mx(12) | BG35: =+CONCATENATE("mx","(",G35,")") -> mx(13) | BH35: =+CONCATENATE("mx","(",H35,")") -> mx(2) | BI35: =+CONCATENATE("mx","(",I35,")") -> mx(3) | BJ35: =+CONCATENATE("mx","(",J35,")") -> mx(4) | ... BQ35: =+CONCATENATE("mx","(",Q35,")") -> mx(15) | BR35: =+CONCATENATE("µ(X)",C35) -> µ(X)1 | BS35: =+CONCATENATE("µ(X)",D35) -> µ(X)10 | BT35: =+CONCATENATE("µ(X)",E35) -> µ(X)11 | BU35: =+CONCATENATE("µ(X)",F35) -> µ(X)12 | BV35: =+CONCATENATE("µ(X)",G35) -> µ(X)13 | BW35: =+CONCATENATE("µ(X)",H35) -> µ(X)2 | BX35: =+CONCATENATE("µ(X)",I35) -> µ(X)3 | BY35: =+CONCATENATE("µ(X)",J35) -> µ(X)4 | ... CF35: =+CONCATENATE("µ(X)",Q35) -> µ(X)15
A36: 0-4 | B36: 2669011.1 | C36: 82 | D36: 35 | E36: 1552 | F36: 2468 | G36: 37 | H36: 159 | I36: 14 | J36: 786 | K36: 32 | L36: 12 | M36: 5626 | N36: 114 | O36: 877 | P36: 21 | Q36: 29 | S36: =+$B$32 -> 1996 | T36: =+A36 -> 0-4 | U36: =+B36 -> 2669011.1 | V36: =+C36 -> 82 | W36: =+D36 -> 35 | X36: =+E36 -> 1552 | Y36: =+F36 -> 2468 | Z36: =+G36 -> 37 | AA36: =+H36 -> 159 | ... AJ36: =+Q36 -> 29 | AK36: =+SUM(V36:AJ36) -> 11844 | AL36: =+V36/$U36 -> 3.072299e-05 | AM36: =+W36/$U36 -> 1.3113471e-05 | AN36: =+X36/$U36 -> 0.00058148878 | AO36: =+Y36/$U36 -> 0.00092468706 | AP36: =+Z36/$U36 -> 1.3862813e-05 | AQ36: =+AA36/$U36 -> 5.9572627e-05 | AR36: =+AB36/$U36 -> 5.2453885e-06 | AS36: =+AC36/$U36 -> 0.0002944911 | ... AZ36: =+AJ36/$U36 -> 1.0865448e-05 | BA36: =+AK36/U36 -> 0.0044375987 | BB36: =+U36-(0.5*AK36) -> 2663089.1 | BC36: =+AL36/(1-(0.5*$BA36)) -> 3.079131e-05 | BD36: =+AM36/(1-(0.5*$BA36)) -> 1.3142632e-05 | BE36: =+AN36/(1-(0.5*$BA36)) -> 0.00058278186 | BF36: =+AO36/(1-(0.5*$BA36)) -> 0.00092674332 | BG36: =+AP36/(1-(0.5*$BA36)) -> 1.389364e-05 | BH36: =+AQ36/(1-(0.5*$BA36)) -> 5.97051e-05 | BI36: =+AR36/(1-(0.5*$BA36)) -> 5.2570529e-06 | BJ36: =+AS36/(1-(0.5*$BA36)) -> 0.00029514597 | ... BQ36: =+AZ36/(1-(0.5*$BA36)) -> 1.088961e-05 | BR36: =+V36/(2*$U36) -> 1.5361495e-05 | BS36: =+W36/(2*$U36) -> 6.5567357e-06 | BT36: =+X36/(2*$U36) -> 0.00029074439 | BU36: =+Y36/(2*$U36) -> 0.00046234353 | BV36: =+Z36/(2*$U36) -> 6.9314063e-06 | BW36: =+AA36/(2*$U36) -> 2.9786313e-05 | BX36: =+AB36/(2*$U36) -> 2.6226943e-06 | BY36: =+AC36/(2*$U36) -> 0.00014724555 | ... CF36: =+AJ36/(2*$U36) -> 5.4327238e-06
A37: 5-14 | B37: 5336689.3 | C37: 50 | D37: 18 | E37: 121 | F37: 79 | G37: 18 | H37: 266 | I37: 18 | J37: 659 | K37: 105 | L37: 16 | M37: 2 | N37: 15 | O37: 82 | P37: 2 | Q37: 34 | S37: =+$B$32 -> 1996 | T37: =+A37 -> 5-14 | U37: =+B37 -> 5336689.3 | V37: =+C37 -> 50 | W37: =+D37 -> 18 | X37: =+E37 -> 121 | Y37: =+F37 -> 79 | Z37: =+G37 -> 18 | AA37: =+H37 -> 266 | ... AJ37: =+Q37 -> 34 | AK37: =+SUM(V37:AJ37) -> 1485 | AL37: =+V37/$U37 -> 9.3691046e-06 | AM37: =+W37/$U37 -> 3.3728777e-06 | AN37: =+X37/$U37 -> 2.2673233e-05 | AO37: =+Y37/$U37 -> 1.4803185e-05 | AP37: =+Z37/$U37 -> 3.3728777e-06 | AQ37: =+AA37/$U37 -> 4.9843637e-05 | AR37: =+AB37/$U37 -> 3.3728777e-06 | AS37: =+AC37/$U37 -> 0.0001234848 | ... AZ37: =+AJ37/$U37 -> 6.3709911e-06 | BA37: =+AK37/U37 -> 0.00027826241 | BB37: =+U37-(0.5*AK37) -> 5335946.8 | BC37: =+AL37/(1-(0.5*$BA37)) -> 9.3704083e-06 | BD37: =+AM37/(1-(0.5*$BA37)) -> 3.373347e-06 | BE37: =+AN37/(1-(0.5*$BA37)) -> 2.2676388e-05 | BF37: =+AO37/(1-(0.5*$BA37)) -> 1.4805245e-05 | BG37: =+AP37/(1-(0.5*$BA37)) -> 3.373347e-06 | BH37: =+AQ37/(1-(0.5*$BA37)) -> 4.9850572e-05 | BI37: =+AR37/(1-(0.5*$BA37)) -> 3.373347e-06 | BJ37: =+AS37/(1-(0.5*$BA37)) -> 0.00012350198 | ... BQ37: =+AZ37/(1-(0.5*$BA37)) -> 6.3718777e-06 | BR37: =+(V36+V37)/(2*$U37) -> 1.2367218e-05 | BS37: =+(W36+W37)/(2*$U37) -> 4.9656254e-06 | BT37: =+(X36+X37)/(2*$U37) -> 0.00015674512 | BU37: =+(Y36+Y37)/(2*$U37) -> 0.00023863109 | BV37: =+(Z36+Z37)/(2*$U37) -> 5.1530075e-06 | BW37: =+(AA36+AA37)/(2*$U37) -> 3.9818695e-05 | BX37: =+(AB36+AB37)/(2*$U37) -> 2.9981135e-06 | BY37: =+(AC36+AC37)/(2*$U37) -> 0.00013538356 | ... CF37: =+(AJ36+AJ37)/(2*$U37) -> 5.9025359e-06
A38: 15-24 | B38: 4328734.7 | C38: 101 | D38: 34 | E38: 66 | F38: 36 | G38: 71 | H38: 301 | I38: 64 | J38: 1352 | K38: 1694 | L38: 51 | M38: 0 | N38: 33 | O38: 90 | P38: 47 | Q38: 27 | S38: =+$B$32 -> 1996 | T38: =+A38 -> 15-24 | U38: =+B38 -> 4328734.7 | V38: =+C38 -> 101 | W38: =+D38 -> 34 | X38: =+E38 -> 66 | Y38: =+F38 -> 36 | Z38: =+G38 -> 71 | AA38: =+H38 -> 301 | ... AJ38: =+Q38 -> 27 | AK38: =+SUM(V38:AJ38) -> 3967 | AL38: =+V38/$U38 -> 2.3332453e-05 | AM38: =+W38/$U38 -> 7.8544892e-06 | AN38: =+X38/$U38 -> 1.524695e-05 | AO38: =+Y38/$U38 -> 8.3165179e-06 | AP38: =+Z38/$U38 -> 1.6402021e-05 | AQ38: =+AA38/$U38 -> 6.953533e-05 | AR38: =+AB38/$U38 -> 1.4784921e-05 | AS38: =+AC38/$U38 -> 0.00031233145 | ... AZ38: =+AJ38/$U38 -> 6.2373884e-06 | BA38: =+AK38/U38 -> 0.00091643407 | BB38: =+U38-(0.5*AK38) -> 4326751.2 | BC38: =+AL38/(1-(0.5*$BA38)) -> 2.3343149e-05 | BD38: =+AM38/(1-(0.5*$BA38)) -> 7.8580899e-06 | BE38: =+AN38/(1-(0.5*$BA38)) -> 1.5253939e-05 | BF38: =+AO38/(1-(0.5*$BA38)) -> 8.3203304e-06 | BG38: =+AP38/(1-(0.5*$BA38)) -> 1.6409541e-05 | BH38: =+AQ38/(1-(0.5*$BA38)) -> 6.9567207e-05 | BI38: =+AR38/(1-(0.5*$BA38)) -> 1.4791699e-05 | BJ38: =+AS38/(1-(0.5*$BA38)) -> 0.00031247463 | ... BQ38: =+AZ38/(1-(0.5*$BA38)) -> 6.2402478e-06 | BR38: =+(V37+V38)/(2*$U38) -> 1.7441586e-05 | BS38: =+(W37+W38)/(2*$U38) -> 6.0063741e-06 | BT38: =+(X37+X38)/(2*$U38) -> 2.1599845e-05 | BU38: =+(Y37+Y38)/(2*$U38) -> 1.3283327e-05 | BV38: =+(Z37+Z38)/(2*$U38) -> 1.028014e-05 | BW38: =+(AA37+AA38)/(2*$U38) -> 6.5492579e-05 | BX38: =+(AB37+AB38)/(2*$U38) -> 9.4715899e-06 | BY38: =+(AC37+AC38)/(2*$U38) -> 0.00023228497 | ... CF38: =+(AJ37+AJ38)/(2*$U38) -> 7.0459388e-06
A39: 25-44 | B39: 6500086.9 | C39: 1265 | D39: 267 | E39: 94 | F39: 65 | G39: 232 | H39: 1734 | I39: 517 | J39: 2393 | K39: 1811 | L39: 272 | M39: 1 | N39: 99 | O39: 191 | P39: 719 | Q39: 111 | S39: =+$B$32 -> 1996 | T39: =+A39 -> 25-44 | U39: =+B39 -> 6500086.9 | V39: =+C39 -> 1265 | W39: =+D39 -> 267 | X39: =+E39 -> 94 | Y39: =+F39 -> 65 | Z39: =+G39 -> 232 | AA39: =+H39 -> 1734 | ... AJ39: =+Q39 -> 111 | AK39: =+SUM(V39:AJ39) -> 9771 | AL39: =+V39/$U39 -> 0.00019461278 | AM39: =+W39/$U39 -> 4.1076374e-05 | AN39: =+X39/$U39 -> 1.4461345e-05 | AO39: =+Y39/$U39 -> 9.9998662e-06 | AP39: =+Z39/$U39 -> 3.569183e-05 | AQ39: =+AA39/$U39 -> 0.00026676566 | AR39: =+AB39/$U39 -> 7.9537398e-05 | AS39: =+AC39/$U39 -> 0.00036814892 | ... AZ39: =+AJ39/$U39 -> 1.7076695e-05 | BA39: =+AK39/U39 -> 0.0015032107 | BB39: =+U39-(0.5*AK39) -> 6495201.4 | BC39: =+AL39/(1-(0.5*$BA39)) -> 0.00019475916 | BD39: =+AM39/(1-(0.5*$BA39)) -> 4.110727e-05 | BE39: =+AN39/(1-(0.5*$BA39)) -> 1.4472222e-05 | BF39: =+AO39/(1-(0.5*$BA39)) -> 1.0007388e-05 | BG39: =+AP39/(1-(0.5*$BA39)) -> 3.5718677e-05 | BH39: =+AQ39/(1-(0.5*$BA39)) -> 0.00026696632 | BI39: =+AR39/(1-(0.5*$BA39)) -> 7.9597223e-05 | BJ39: =+AS39/(1-(0.5*$BA39)) -> 0.00036842583 | ... BQ39: =+AZ39/(1-(0.5*$BA39)) -> 1.7089539e-05 | BR39: =+(V38+V39)/(2*$U39) -> 0.00010507552 | BS39: =+(W38+W39)/(2*$U39) -> 2.3153536e-05 | BT39: =+(X38+X39)/(2*$U39) -> 1.2307528e-05 | BU39: =+(Y38+Y39)/(2*$U39) -> 7.7691269e-06 | BV39: =+(Z38+Z39)/(2*$U39) -> 2.3307381e-05 | BW39: =+(AA38+AA39)/(2*$U39) -> 0.00015653637 | BX39: =+(AB38+AB39)/(2*$U39) -> 4.469171e-05 | BY39: =+(AC38+AC39)/(2*$U39) -> 0.00028807307 | ... CF39: =+(AJ38+AJ39)/(2*$U39) -> 1.0615243e-05
A40: 45-64 | B40: 2862216.5 | C40: 5170 | D40: 791 | E40: 38 | F40: 151 | G40: 387 | H40: 4424 | I40: 1783 | J40: 1078 | K40: 502 | L40: 1450 | M40: 0 | N40: 427 | O40: 247 | P40: 130 | Q40: 206 | S40: =+$B$32 -> 1996 | T40: =+A40 -> 45-64 | U40: =+B40 -> 2862216.5 | V40: =+C40 -> 5170 | W40: =+D40 -> 791 | X40: =+E40 -> 38 | Y40: =+F40 -> 151 | Z40: =+G40 -> 387 | AA40: =+H40 -> 4424 | ... AJ40: =+Q40 -> 206 | AK40: =+SUM(V40:AJ40) -> 16784 | AL40: =+V40/$U40 -> 0.0018062924 | AM40: =+W40/$U40 -> 0.00027635925 | AN40: =+X40/$U40 -> 1.3276424e-05 | AO40: =+Y40/$U40 -> 5.2756317e-05 | AP40: =+Z40/$U40 -> 0.0001352099 | AQ40: =+AA40/$U40 -> 0.0015456553 | AR40: =+AB40/$U40 -> 0.0006229438 | AS40: =+AC40/$U40 -> 0.00037663119 | ... AZ40: =+AJ40/$U40 -> 7.1972194e-05 | BA40: =+AK40/U40 -> 0.0058639869 | BB40: =+U40-(0.5*AK40) -> 2853824.5 | BC40: =+AL40/(1-(0.5*$BA40)) -> 0.0018116041 | BD40: =+AM40/(1-(0.5*$BA40)) -> 0.00027717192 | BE40: =+AN40/(1-(0.5*$BA40)) -> 1.3315465e-05 | BF40: =+AO40/(1-(0.5*$BA40)) -> 5.2911453e-05 | BG40: =+AP40/(1-(0.5*$BA40)) -> 0.0001356075 | BH40: =+AQ40/(1-(0.5*$BA40)) -> 0.0015502004 | BI40: =+AR40/(1-(0.5*$BA40)) -> 0.00062477563 | BJ40: =+AS40/(1-(0.5*$BA40)) -> 0.00037773872 | ... BQ40: =+AZ40/(1-(0.5*$BA40)) -> 7.2183836e-05 | BR40: =+(V39+V40)/(2*$U40) -> 0.0011241288 | BS40: =+(W39+W40)/(2*$U40) -> 0.0001848218 | BT40: =+(X39+X40)/(2*$U40) -> 2.3059052e-05 | BU40: =+(Y39+Y40)/(2*$U40) -> 3.7732995e-05 | BV40: =+(Z39+Z40)/(2*$U40) -> 0.00010813298 | BW40: =+(AA39+AA40)/(2*$U40) -> 0.0010757397 | BX40: =+(AB39+AB40)/(2*$U40) -> 0.00040178652 | BY40: =+(AC39+AC40)/(2*$U40) -> 0.00060634827 | ... CF40: =+(AJ39+AJ40)/(2*$U40) -> 5.5376664e-05
A41: 65-74 | B41: 710343.29 | C41: 5212 | D41: 406 | E41: 24 | F41: 146 | G41: 319 | H41: 3335 | I41: 1780 | J41: 380 | K41: 125 | L41: 1343 | M41: 0 | N41: 576 | O41: 226 | P41: 5 | Q41: 161 | S41: =+$B$32 -> 1996 | T41: =+A41 -> 65-74 | U41: =+B41 -> 710343.29 | V41: =+C41 -> 5212 | W41: =+D41 -> 406 | X41: =+E41 -> 24 | Y41: =+F41 -> 146 | Z41: =+G41 -> 319 | AA41: =+H41 -> 3335 | ... AJ41: =+Q41 -> 161 | AK41: =+SUM(V41:AJ41) -> 14038 | AL41: =+V41/$U41 -> 0.0073372975 | AM41: =+W41/$U41 -> 0.00057155464 | AN41: =+X41/$U41 -> 3.3786481e-05 | AO41: =+Y41/$U41 -> 0.00020553443 | AP41: =+Z41/$U41 -> 0.00044907864 | AQ41: =+AA41/$U41 -> 0.0046949131 | AR41: =+AB41/$U41 -> 0.0025058307 | AS41: =+AC41/$U41 -> 0.00053495262 | ... AZ41: =+AJ41/$U41 -> 0.00022665098 | BA41: =+AK41/U41 -> 0.019762276 | BB41: =+U41-(0.5*AK41) -> 703324.29 | BC41: =+AL41/(1-(0.5*$BA41)) -> 0.0074105218 | BD41: =+AM41/(1-(0.5*$BA41)) -> 0.00057725861 | BE41: =+AN41/(1-(0.5*$BA41)) -> 3.4123662e-05 | BF41: =+AO41/(1-(0.5*$BA41)) -> 0.00020758561 | BG41: =+AP41/(1-(0.5*$BA41)) -> 0.00045356034 | BH41: =+AQ41/(1-(0.5*$BA41)) -> 0.0047417671 | BI41: =+AR41/(1-(0.5*$BA41)) -> 0.0025308382 | BJ41: =+AS41/(1-(0.5*$BA41)) -> 0.00054029131 | ... BQ41: =+AZ41/(1-(0.5*$BA41)) -> 0.0002289129 | BR41: =+(V40+V41)/(2*$U41) -> 0.0073077343 | BS41: =+(W40+W41)/(2*$U41) -> 0.00084255037 | BT41: =+(X40+X41)/(2*$U41) -> 4.3640871e-05 | BU41: =+(Y40+Y41)/(2*$U41) -> 0.00020905385 | BV41: =+(Z40+Z41)/(2*$U41) -> 0.00049694282 | BW41: =+(AA40+AA41)/(2*$U41) -> 0.0054614439 | BX41: =+(AB40+AB41)/(2*$U41) -> 0.0025079423 | BY41: =+(AC40+AC41)/(2*$U41) -> 0.0010262644 | ... CF41: =+(AJ40+AJ41)/(2*$U41) -> 0.0002583258
A42: 75+ | B42: 710343.29 | C42: 9429 | D42: 279 | E42: 22 | F42: 432 | G42: 397 | H42: 3401 | I42: 3442 | J42: 534 | K42: 68 | L42: 1306 | M42: 14 | N42: 1141 | O42: 974 | P42: 7 | Q42: 178 | S42: =+$B$32 -> 1996 | T42: =+A42 -> 75+ | U42: =+B42 -> 710343.29 | V42: =+C42 -> 9429 | W42: =+D42 -> 279 | X42: =+E42 -> 22 | Y42: =+F42 -> 432 | Z42: =+G42 -> 397 | AA42: =+H42 -> 3401 | ... AJ42: =+Q42 -> 178 | AK42: =+SUM(V42:AJ42) -> 21624 | AL42: =+V42/$U42 -> 0.013273864 | AM42: =+W42/$U42 -> 0.00039276784 | AN42: =+X42/$U42 -> 3.0970941e-05 | AO42: =+Y42/$U42 -> 0.00060815666 | AP42: =+Z42/$U42 -> 0.00055888471 | AQ42: =+AA42/$U42 -> 0.0047878259 | AR42: =+AB42/$U42 -> 0.0048455445 | AS42: =+AC42/$U42 -> 0.0007517492 | ... AZ42: =+AJ42/$U42 -> 0.00025058307 | BA42: =+AK42/U42 -> 0.030441619 | BB42: =+U42-(0.5*AK42) -> 699531.29 | BC42: =+AL42/(1-(0.5*$BA42)) -> 0.013479025 | BD42: =+AM42/(1-(0.5*$BA42)) -> 0.00039883849 | BE42: =+AN42/(1-(0.5*$BA42)) -> 3.144963e-05 | BF42: =+AO42/(1-(0.5*$BA42)) -> 0.00061755637 | BG42: =+AP42/(1-(0.5*$BA42)) -> 0.00056752286 | BH42: =+AQ42/(1-(0.5*$BA42)) -> 0.0048618269 | BI42: =+AR42/(1-(0.5*$BA42)) -> 0.0049204375 | BJ42: =+AS42/(1-(0.5*$BA42)) -> 0.00076336829 | ... BQ42: =+AZ42/(1-(0.5*$BA42)) -> 0.0002544561 | BR42: =+(V41+V42)/(2*$U42) -> 0.010305581 | BS42: =+(W41+W42)/(2*$U42) -> 0.00048216124 | BT42: =+(X41+X42)/(2*$U42) -> 3.2378711e-05 | BU42: =+(Y41+Y42)/(2*$U42) -> 0.00040684554 | BV42: =+(Z41+Z42)/(2*$U42) -> 0.00050398168 | BW42: =+(AA41+AA42)/(2*$U42) -> 0.0047413695 | BX42: =+(AB41+AB42)/(2*$U42) -> 0.0036756876 | BY42: =+(AC41+AC42)/(2*$U42) -> 0.00064335091 | ... CF42: =+(AJ41+AJ42)/(2*$U42) -> 0.00023861702
A45: Año | B45: 1996
A47: Suma de Fallecimientos | C47: Posicion
A48: Grupo Etario | B48: Población | C48: 1 | D48: 10 | E48: 11 | F48: 12 | G48: 13 | H48: 2 | I48: 3 | J48: 4 | K48: 5 | L48: 6 | M48: 7 | N48: 8 | O48: 9 | P48: 14 | Q48: 15 | S48: Año | T48: Grupo Etario | U48: lx(T) | V48: =+CONCATENATE("dx","(",C48,")") -> dx(1) | W48: =+CONCATENATE("dx","(",D48,")") -> dx(10) | X48: =+CONCATENATE("dx","(",E48,")") -> dx(11) | Y48: =+CONCATENATE("dx","(",F48,")") -> dx(12) | Z48: =+CONCATENATE("dx","(",G48,")") -> dx(13) | AA48: =+CONCATENATE("dx","(",H48,")") -> dx(2) | AB48: =+CONCATENATE("dx","(",I48,")") -> dx(3) | AC48: =+CONCATENATE("dx","(",J48,")") -> dx(4) | ... AJ48: =+CONCATENATE("dx","(",Q48,")") -> dx(15) | AK48: dx(T) | AL48: =+CONCATENATE("qx","(",C48,")") -> qx(1) | AM48: =+CONCATENATE("qx","(",D48,")") -> qx(10) | AN48: =+CONCATENATE("qx","(",E48,")") -> qx(11) | AO48: =+CONCATENATE("qx","(",F48,")") -> qx(12) | AP48: =+CONCATENATE("qx","(",G48,")") -> qx(13) | AQ48: =+CONCATENATE("qx","(",H48,")") -> qx(2) | AR48: =+CONCATENATE("qx","(",I48,")") -> qx(3) | AS48: =+CONCATENATE("qx","(",J48,")") -> qx(4) | ... AZ48: =+CONCATENATE("qx","(",Q48,")") -> qx(15) | BA48: =+CONCATENATE("qx","(T)") -> qx(T) | BB48: Lx(T) | BC48: =+CONCATENATE("mx","(",C48,")") -> mx(1) | BD48: =+CONCATENATE("mx","(",D48,")") -> mx(10) | BE48: =+CONCATENATE("mx","(",E48,")") -> mx(11) | BF48: =+CONCATENATE("mx","(",F48,")") -> mx(12) | BG48: =+CONCATENATE("mx","(",G48,")") -> mx(13) | BH48: =+CONCATENATE("mx","(",H48,")") -> mx(2) | BI48: =+CONCATENATE("mx","(",I48,")") -> mx(3) | BJ48: =+CONCATENATE("mx","(",J48,")") -> mx(4) | ... BQ48: =+CONCATENATE("mx","(",Q48,")") -> mx(15) | BR48: =+CONCATENATE("µ(X)",C48) -> µ(X)1 | BS48: =+CONCATENATE("µ(X)",D48) -> µ(X)10 | BT48: =+CONCATENATE("µ(X)",E48) -> µ(X)11 | BU48: =+CONCATENATE("µ(X)",F48) -> µ(X)12 | BV48: =+CONCATENATE("µ(X)",G48) -> µ(X)13 | BW48: =+CONCATENATE("µ(X)",H48) -> µ(X)2 | BX48: =+CONCATENATE("µ(X)",I48) -> µ(X)3 | BY48: =+CONCATENATE("µ(X)",J48) -> µ(X)4 | ... CF48: =+CONCATENATE("µ(X)",Q48) -> µ(X)15
A49: 0-4 | B49: 2669011.1 | C49: 82 | D49: 35 | E49: 1552 | F49: 2468 | G49: 37 | H49: 159 | I49: 14 | J49: 786 | K49: 32 | L49: 12 | M49: 5626 | N49: 114 | O49: 877 | P49: 21 | Q49: 29 | S49: =+$B$45 -> 1996 | T49: =+A49 -> 0-4 | U49: =+B49 -> 2669011.1 | V49: =+C49 -> 82 | W49: =+D49 -> 35 | X49: =+E49 -> 1552 | Y49: =+F49 -> 2468 | Z49: =+G49 -> 37 | AA49: =+H49 -> 159 | ... AJ49: =+Q49 -> 29 | AK49: =+SUM(V49:AJ49) -> 11844 | AL49: =+V49/$U49 -> 3.072299e-05 | AM49: =+W49/$U49 -> 1.3113471e-05 | AN49: =+X49/$U49 -> 0.00058148878 | AO49: =+Y49/$U49 -> 0.00092468706 | AP49: =+Z49/$U49 -> 1.3862813e-05 | AQ49: =+AA49/$U49 -> 5.9572627e-05 | AR49: =+AB49/$U49 -> 5.2453885e-06 | AS49: =+AC49/$U49 -> 0.0002944911 | ... AZ49: =+AJ49/$U49 -> 1.0865448e-05 | BA49: =+AK49/U49 -> 0.0044375987 | BB49: =+U49-(0.5*AK49) -> 2663089.1 | BC49: =+AL49/(1-(0.5*$BA49)) -> 3.079131e-05 | BD49: =+AM49/(1-(0.5*$BA49)) -> 1.3142632e-05 | BE49: =+AN49/(1-(0.5*$BA49)) -> 0.00058278186 | BF49: =+AO49/(1-(0.5*$BA49)) -> 0.00092674332 | BG49: =+AP49/(1-(0.5*$BA49)) -> 1.389364e-05 | BH49: =+AQ49/(1-(0.5*$BA49)) -> 5.97051e-05 | BI49: =+AR49/(1-(0.5*$BA49)) -> 5.2570529e-06 | BJ49: =+AS49/(1-(0.5*$BA49)) -> 0.00029514597 | ... BQ49: =+AZ49/(1-(0.5*$BA49)) -> 1.088961e-05 | BR49: =+V49/(2*$U49) -> 1.5361495e-05 | BS49: =+W49/(2*$U49) -> 6.5567357e-06 | BT49: =+X49/(2*$U49) -> 0.00029074439 | BU49: =+Y49/(2*$U49) -> 0.00046234353 | BV49: =+Z49/(2*$U49) -> 6.9314063e-06 | BW49: =+AA49/(2*$U49) -> 2.9786313e-05 | BX49: =+AB49/(2*$U49) -> 2.6226943e-06 | BY49: =+AC49/(2*$U49) -> 0.00014724555 | ... CF49: =+AJ49/(2*$U49) -> 5.4327238e-06
...

Sheet BD_Mujeres
A1: key | B1: Año | C1: Grupo Etario | D1: Sexo | E1: Posicion | F1: Enfermedad | G1: Fallecimientos | H1: Población
A2: =+CONCATENATE(B2,C2) -> 19960-4 | B2: 1996 | C2: 0-4 | D2: F | E2: 1 | F2: Enfermedades del Corazón (I05-I09, I11, I13, I21-I51) | G2: 38 | H2: 1308550.8
A3: =+CONCATENATE(B3,C3) -> 199615-24 | B3: 1996 | C3: 15-24 | D3: F | E3: 1 | F3: Enfermedades del Corazón (I05-I09, I11, I13, I21-I51) | G3: 40 | H3: 2136825.7
A4: =+CONCATENATE(B4,C4) -> 199625-44 | B4: 1996 | C4: 25-44 | D4: F | E4: 1 | F4: Enfermedades del Corazón (I05-I09, I11, I13, I21-I51) | G4: 467 | H4: 3245545.3
A5: =+CONCATENATE(B5,C5) -> 199645-64 | B5: 1996 | C5: 45-64 | D5: F | E5: 1 | F5: Enfermedades del Corazón (I05-I09, I11, I13, I21-I51) | G5: 1724 | H5: 1448878
A6: =+CONCATENATE(B6,C6) -> 19965-14 | B6: 1996 | C6: 5-14 | D6: F | E6: 1 | F6: Enfermedades del Corazón (I05-I09, I11, I13, I21-I51) | G6: 24 | H6: 2617766.7
A7: =+CONCATENATE(B7,C7) -> 199665-74 | B7: 1996 | C7: 65-74 | D7: F | E7: 1 | F7: Enfermedades del Corazón (I05-I09, I11, I13, I21-I51) | G7: 2053 | H7: 373487.34
A8: =+CONCATENATE(B8,C8) -> 199675+ | B8: 1996 | C8: 75+ | D8: F | E8: 1 | F8: Enfermedades del Corazón (I05-I09, I11, I13, I21-I51) | G8: 5003 | H8: 186458.59
A9: =+CONCATENATE(B9,C9) -> 19970-4 | B9: 1997 | C9: 0-4 | D9: F | E9: 1 | F9: Enfermedades del Corazón (I05-I09, I11, I13, I21-I51) | G9: 28 | H9: 1317732.9
A10: =+CONCATENATE(B10,C10) -> 199715-24 | B10: 1997 | C10: 15-24 | D10: F | E10: 1 | F10: Enfermedades del Corazón (I05-I09, I11, I13, I21-I51) | G10: 78 | H10: 2190257.4
A11: =+CONCATENATE(B11,C11) -> 199725-44 | B11: 1997 | C11: 25-44 | D11: F | E11: 1 | F11: Enfermedades del Corazón (I05-I09, I11, I13, I21-I51) | G11: 441 | H11: 3319789
A12: =+CONCATENATE(B12,C12) -> 199745-64 | B12: 1997 | C12: 45-64 | D12: F | E12: 1 | F12: Enfermedades del Corazón (I05-I09, I11, I13, I21-I51) | G12: 1786 | H12: 1494497.8
A13: =+CONCATENATE(B13,C13) -> 19975-14 | B13: 1997 | C13: 5-14 | D13: F | E13: 1 | F13: Enfermedades del Corazón (I05-I09, I11, I13, I21-I51) | G13: 24 | H13: 2625110
... A134: =+CONCATENATE(B134,C134) -> 201475+ | B134: 2014 | C134: 75+ | D134: F | E134: 1 | F134: Enfermedades del Corazón (I05-I09, I11, I13, I21-I51) | G134: 9094 | H134: 425486
A135: =+CONCATENATE(B135,C135) -> 19960-4 | B135: 1996 | C135: 0-4 | D135: F | E135: 2 | F135: Cancer (C00-C97) | G135: 62 | H135: 1308550.8
A136: =+CONCATENATE(B136,C136) -> 199615-24 | B136: 1996 | C136: 15-24 | D136: F | E136: 2 | F136: Cancer (C00-C97) | G136: 130 | H136: 2136825.7
A137: =+CONCATENATE(B137,C137) -> 199625-44 | B137: 1996 | C137: 25-44 | D137: F | E137: 2 | F137: Cancer (C00-C97) | G137: 1119 | H137: 3245545.3
A138: =+CONCATENATE(B138,C138) -> 199645-64 | B138: 1996 | C138: 45-64 | D138: F | E138: 2 | F138: Cancer (C00-C97) | G138: 2420 | H138: 1448878
A139: =+CONCATENATE(B139,C139) -> 19965-14 | B139: 1996 | C139: 5-14 | D139: F | E139: 2 | F139: Cancer (C00-C97) | G139: 114 | H139: 2617766.7
A140: =+CONCATENATE(B140,C140) -> 199665-74 | B140: 1996 | C140: 65-74 | D140: F | E140: 2 | F140: Cancer (C00-C97) | G140: 1478 | H140: 373487.34
A141: =+CONCATENATE(B141,C141) -> 199675+ | B141: 1996 | C141: 75+ | D141: F | E141: 2 | F141: Cancer (C00-C97) | G141: 1582 | H141: 186458.59
