Workbook
Name \a: #REF!
Name \a: #REF!
Name \a: #REF!
Name \a: #REF!
Name \a: #REF!
Name \a: #REF!
Name \a: #REF!
Name \a: #REF!
Name \a: #REF!
Name \a: #REF!
Name \b: [1]CEN90PU8!$IN$96
Name \c: [1]CEN90PU8!$IH$96
Name \d: [1]CE90PU26!$IS$97
Name \e: [1]CE90PU26!$IV$8192
Name \f: [1]CE90PU25!$IS$100
Name \g: [1]CE90PU25!$IC$248
Name \h: [1]CE90PU25!$IL$105
Name \i: [1]CE90PU25!$C$113
Name \j: [1]CE90PU25!$F$113
Name \k: [1]CE90PU25!$M$100
Name \u: [1]CEN90PU8!$IH$264
Name \w: [1]CE90PU26!$IV$8192
Name \x: [1]CE90PU25!$C$101
Name \y: [1]CE90PU25!$IE$255
Name \z: [1]CEN90PU8!$IN$102
Name _1: #REF!
Name _1: #REF!
Name _1: #REF!
Name _1: #REF!
Name _1: #REF!
Name _2: #REF!
Name _2: #REF!
Name _2: #REF!
Name _2: #REF!
Name _2: #REF!
Name _3: #REF!
Name _3: #REF!
Name _3: #REF!
Name _3: #REF!
Name _3: #REF!
Name _4: #REF!
Name _4: #REF!
Name _4: #REF!
Name _4: #REF!
Name _4: #REF!
Name _5: #REF!
Name _5: #REF!
Name _5: #REF!
Name _5: #REF!
Name _5: #REF!
Name _PAS1: [2]Anaco!#REF!
Name _PAS1: [2]Anaco!#REF!
Name _PAS1: [2]Anaco!#REF!
Name _PAS1: [2]Anaco!#REF!
Name _PAS1: [2]Anaco!#REF!
Name _PAS1: [2]Anaco!#REF!
Name _PAS1: [2]Anaco!#REF!
Name _PAS1: [2]Anaco!#REF!
Name _PAS1: [2]Anaco!#REF!
Name _PAS1: [2]Anaco!#REF!

Sheet Resumen
A1: Resumen por hoja
A2: info ine: | B2: Contiene información de la composición etaria de venezuela por cada edad, con esto se calculó la distribución porcentual de cada edad dentro de los grupos de edades con la finalidad de estimar la población y muertes de cada edad
A3: Mortalidad: | B3: Contiene la información obtenida de Portal del MPPS referente a las muertes ocurridas en venezuela desde el 1995 al 2011
A4: Mortalidad1: | B4: Se filtraron los totales por edades
A5: Población: | B5: Del Instituto Nacional de Estadística, (INE) se compiló la información censal y se crearon interpolaciones por cada grupo de edad para estimar la población desde 1995 al 2011
A6: Población por Edad: | B6: Se aplicaron los porcentajes calculados en "info ine" se aplicaron a las estimaciones resultantes de "población" para obtener la población por edad
A7: Muertes por Edad: | B7: Se aplicaron los porcentajes calculados en "info ine" se aplicaron a la información de "Mortalidad1" para obtener las muertes por edad
A8: Qx: | B8: Se calculó la mortalidad por edad en el período 1995 - 2011, se promediaron las tasas y se ajustó un polinomio de 4° grado para obtener la estimación de la mortalidad en Venezulea
A9: Comparación: | B9: Se compara por medio de mínimos cuadrados (K) la estimación calculada en Qx contra algunas tablas encontradas, el mejor ajuste se obtiene con la tabla más actual encontrada procedente del seguro social de america (http://www.ssa.gov/OACT/STATS/table4c6.html)

Sheet info ine
A1: POBLACION POR GRUPO DE EDAD DE VENEZUELA | CN1: POBLACION POR GRUPO DE EDAD DE VENEZUELA
A3: GRUPOS | CN3: EDAD/ANO | CO3: 1990 | CP3: 1991 | CQ3: 1992 | CR3: 1993 | CS3: 1994 | CT3: 1995 | CU3: 1996 | CV3: 1997 | CW3: 1998 | CX3: 1999 | CY3: 2000 | CZ3: 2001 | DA3: 2002 | DB3: 2003 | DC3: 2004 | DD3: 2005 | DE3: 2006 | DF3: 2007 | DG3: 2008 | DH3: 2009 | DI3: 2010 | DJ3: 2011 | DK3: 2012 | DL3: 2013 | DM3: 2014 | DN3: 2015 | DO3: 2016 | DP3: 2017 | DQ3: 2018 | DR3: 2019 | DS3: 2020 | DT3: 2021 | DU3: 2022 | DV3: 2023 | DW3: 2024 | DX3: 2025 | DY3: 2026 | DZ3: 2027 | EA3: 2028 | EB3: 2029 | EC3: 2030 | ED3: 2031 | EE3: 2032 | EF3: 2033 | EG3: 2034 | EH3: 2035 | EI3: 2036 | EJ3: 2037 | EK3: 2038 | EL3: 2039 | EM3: 2040 | EN3: 2041 | EO3: 2042 | EP3: 2043 | EQ3: 2044 | ER3: 2045 | ES3: 2046 | ET3: 2047 | EU3: 2048 | EV3: 2049 | EW3: 2050
A4: DE EDAD | B4: 2000 | D4: 2001 | E4: 2002 | F4: 2003 | G4: 2004 | H4: 2005 | I4: 2006 | J4: 2007 | K4: 2008 | L4: 2009 | M4: 2010 | N4: 2011 | O4: 2012 | P4: 2013 | Q4: 2014 | R4: 2015 | S4: 2016 | T4: 2017 | U4: 2018 | V4: 2019 | W4: 2020 | X4: 2021 | Y4: 2022 | Z4: 2023 | AA4: 2024 | AB4: 2025 | AC4: 2026 | AD4: 2027
CN5: HOMBRES | CO5: 9956666 | CP5: 10186733 | CQ5: 10416960 | CR5: 10647110 | CS5: 10876944 | CT5: 11106197 | CU5: 11333607 | CV5: 11559949 | CW5: 11784967 | CX5: 12010280 | CY5: 12229953 | CZ5: 12454204 | DA5: 12678275 | DB5: 12901999 | DC5: 13125804 | DD5: 13347732 | DE5: 13570418 | DF5: 13792761 | DG5: 14014614 | DH5: 14235351 | DI5: 14456287 | DJ5: 14673402 | DK5: 14888876 | DL5: 15102533 | DM5: 15313881 | DN5: 15523702 | DO5: 15728959 | DP5: 15931336 | DQ5: 16130644 | DR5: 16326788 | DS5: 16519307 | DT5: 16707676 | DU5: 16892332 | DV5: 17073102 | DW5: 17250156 | DX5: 17422288 | DY5: 17590805 | DZ5: 17755123 | EA5: 17915090 | EB5: 18070999 | EC5: 18221385 | ED5: 18368445 | EE5: 18511038 | EF5: 18649038 | EG5: 18782673 | EH5: 18910790 | EI5: 19035147 | EJ5: 19154801 | EK5: 19269651 | EL5: 19379606 | EM5: 19484556 | EN5: 19584545 | EO5: 19679355 | EP5: 19768907 | EQ5: 19854961 | ER5: 19931944 | ES5: 20011039 | ET5: 20086480 | EU5: 20158221 | EV5: 20226221 | EW5: 20290430
A6: TOTAL | B6: 24310896 | D6: 24765581 | E6: 25219910 | F6: 25673550 | G6: 26127351 | H6: 26577423 | I6: 27030656 | J6: 27483208 | K6: 27934783 | L6: 28384132 | M6: 28833845 | N6: 29277736 | O6: 29718357 | P6: 30155352 | Q6: 30587736 | R6: 31017064 | S6: 31439105 | T6: 31855396 | U6: 32265553 | V6: 32669379 | W6: 33065965 | X6: 33456022 | Y6: 33838655 | Z6: 34213506 | AA6: 34580906 | AB6: 34938434 | AC6: 35289945 | AD6: 35633043
A8: 0-4
A9: 0 | B9: 553335 | C9: =+B9/B14 -> 0.20008085 | D9: 560034 | E9: 566727 | F9: 573402 | G9: 580080 | H9: 586678 | I9: 587449 | J9: 588204 | K9: 588939 | L9: 589626 | M9: 590326 | N9: 588794 | O9: 587193 | P9: 585519 | Q9: 583756 | R9: 581937 | S9: 579930 | T9: 577810 | U9: 575577 | V9: 573232 | W9: 570768 | X9: 569005 | Y9: 567110 | Z9: 565083 | AA9: 562935 | AB9: 560631 | AC9: 558715 | AD9: 556661
A10: 1 | B10: 555223 | C10: =+B10/B14 -> 0.20076354 | D10: 559206 | E10: 563181 | F10: 567141 | G10: 571103 | H10: 574986 | I10: 577156 | J10: 579311 | K10: 581446 | L10: 583534 | M10: 585634 | N10: 585417 | O10: 585132 | P10: 584775 | Q10: 584328 | R10: 583826 | S10: 582079 | T10: 580219 | U10: 578246 | V10: 576161 | W10: 573954 | X10: 571884 | Y10: 569680 | Z10: 567343 | AA10: 564884 | AB10: 562271 | AC10: 560177 | AD10: 557944
A11: 2 | B11: 554738 | C11: =+B11/B14 -> 0.20058816 | D11: 557062 | E11: 559377 | F11: 561677 | G11: 563979 | H11: 566203 | I11: 569316 | J11: 572414 | K11: 575491 | L11: 578523 | M11: 581566 | N11: 582337 | O11: 583041 | P11: 583672 | Q11: 584216 | R11: 584703 | S11: 583254 | T11: 581693 | U11: 580019 | V11: 578233 | W11: 576324 | X11: 574108 | Y11: 571758 | Z11: 569274 | AA11: 566669 | AB11: 563908 | AC11: 561718 | AD11: 559388
A12: 3 | B12: 552627 | C12: =+B12/B14 -> 0.19982485 | D12: 554100 | E12: 555564 | F12: 557012 | G12: 558464 | H12: 559837 | I12: 563502 | J12: 567151 | K12: 570780 | L12: 574364 | M12: 577958 | N12: 579450 | O12: 580874 | P12: 582226 | Q12: 583490 | R12: 584698 | S12: 583588 | T12: 582365 | U12: 581029 | V12: 579580 | W12: 578008 | X12: 575785 | Y12: 573429 | Z12: 570939 | AA12: 568326 | AB12: 565558 | AC12: 563337 | AD12: 560976
A13: 4 | B13: 549634 | C13: =+B13/B14 -> 0.1987426 | D13: 550816 | E13: 551991 | F13: 553149 | G13: 554310 | H13: 555394 | I13: 559284 | J13: 563160 | K13: 567016 | L13: 570826 | M13: 574647 | N13: 576649 | O13: 578585 | P13: 580449 | Q13: 582225 | R13: 583946 | S13: 583212 | T13: 582366 | U13: 581406 | V13: 580335 | W13: 579137 | X13: 577025 | Y13: 574779 | Z13: 572398 | AA13: 569894 | AB13: 567233 | AC13: 565034 | AD13: 562693
A14: 5-9 | B14: =SUM(B9:B13) -> 2765557 | D14: =SUM(D9:D13) -> 2781218 | E14: =SUM(E9:E13) -> 2796840 | F14: =SUM(F9:F13) -> 2812381 | G14: =SUM(G9:G13) -> 2827936 | H14: =SUM(H9:H13) -> 2843098 | I14: =SUM(I9:I13) -> 2856707 | J14: =SUM(J9:J13) -> 2870240 | K14: =SUM(K9:K13) -> 2883672 | ... AD14: =SUM(AD9:AD13) -> 2797662
A15: 5 | B15: 546548 | C15: =+B15/B20 -> 0.20077275 | D15: 547741 | E15: 548927 | F15: 550097 | G15: 551269 | H15: 552365 | I15: 556222 | J15: 560066 | K15: 563890 | L15: 567668 | M15: 571456 | N15: 573823 | O15: 576125 | P15: 578353 | Q15: 580495 | R15: 582583 | S15: 582264 | T15: 581834 | U15: 581290 | V15: 580634 | W15: 579852 | X15: 577940 | Y15: 575895 | Z15: 573716 | AA15: 571413 | AB15: 568953 | AC15: 566807 | AD15: 564520
A16: 6 | B16: 544113 | C16: =+B16/B20 -> 0.19987826 | D16: 545372 | E16: 546622 | F16: 547856 | G16: 549094 | H16: 550254 | I16: 553888 | J16: 557506 | K16: 561105 | L16: 564659 | M16: 568223 | N16: 570867 | O16: 573445 | P16: 575953 | Q16: 578373 | R16: 580740 | S16: 580875 | T16: 580899 | U16: 580810 | V16: 580609 | W16: 580281 | X16: 578640 | Y16: 576865 | Z16: 574954 | AA16: 572921 | AB16: 570730 | AC16: 568657 | AD16: 566444
A17: 7 | B17: 542938 | C17: =+B17/B20 -> 0.19944663 | D17: 544105 | E17: 545262 | F17: 546404 | G17: 547550 | H17: 548617 | I17: 551895 | J17: 555159 | K17: 558402 | L17: 561602 | M17: 564810 | N17: 567696 | O17: 570516 | P17: 573266 | Q17: 575929 | R17: 578539 | S17: 579165 | T17: 579680 | U17: 580082 | V17: 580373 | W17: 580537 | X17: 579212 | Y17: 577754 | Z17: 576160 | AA17: 574443 | AB17: 572567 | AC17: 570576 | AD17: 568442
A18: 8 | B18: 543406 | C18: =+B18/B20 -> 0.19961855 | D18: 544172 | E18: 544929 | F18: 545671 | G18: 546416 | H18: 547083 | I18: 549932 | J18: 552766 | K18: 555580 | L18: 558350 | M18: 561129 | N18: 564260 | O18: 567325 | P18: 570321 | Q18: 573231 | R18: 576085 | S18: 577232 | T18: 578270 | U18: 579195 | V18: 580008 | W18: 580695 | X18: 579716 | Y18: 578603 | Z18: 577355 | AA18: 575983 | AB18: 574452 | AC18: 572538 | AD18: 570482
A19: 9 | B19: 545217 | C19: =+B19/B20 -> 0.20028381 | D19: 545307 | E19: 545388 | F19: 545454 | G19: 545523 | H19: 545513 | I19: 547898 | J19: 550267 | K19: 552617 | L19: 554923 | M19: 557237 | N19: 560615 | O19: 563928 | P19: 567172 | Q19: 570330 | R19: 573431 | S19: 575115 | T19: 576691 | U19: 578154 | V19: 579505 | W19: 580731 | X19: 580117 | Y19: 579370 | Z19: 578488 | AA19: 577481 | AB19: 576314 | AC19: 574481 | AD19: 572505
A20: 10-14 | B20: =SUM(B15:B19) -> 2722222 | D20: 0 | E20: 0 | F20: 0 | G20: 0 | H20: 0 | I20: 0 | J20: 0 | K20: 0 | L20: 0 | M20: 0 | N20: 0 | O20: 0 | P20: 0 | Q20: 0 | R20: 0 | S20: 0 | T20: 0 | U20: 0 | V20: 0 | W20: 0 | X20: 0 | Y20: 0 | Z20: 0 | AA20: 0 | AB20: 0 | AC20: 0 | AD20: 0
A21: 10 | B21: 547352 | C21: =+B21/B26 -> 0.20207706 | D21: 546716 | E21: 546071 | F21: 545411 | G21: 544755 | H21: 544018 | I21: 545923 | J21: 547813 | K21: 549682 | L21: 551508 | M21: 553343 | N21: 556928 | O21: 560448 | P21: 563900 | Q21: 567266 | R21: 570575 | S21: 572784 | T21: 574887 | U21: 576876 | V21: 578755 | W21: 580508 | X21: 580282 | Y21: 579923 | Z21: 579429 | AA21: 578809 | AB21: 578030 | AC21: 576296 | AD21: 574419
A22: 11 | B22: 548152 | C22: =+B22/B26 -> 0.20237242 | D22: 547138 | E22: 546115 | F22: 545075 | G22: 544040 | H22: 542924 | I22: 544337 | J22: 545735 | K22: 547113 | L22: 548448 | M22: 549791 | N22: 553464 | O22: 557073 | P22: 560613 | Q22: 564069 | R22: 567464 | S22: 570153 | T22: 572734 | U22: 575204 | V22: 577562 | W22: 579797 | X22: 579992 | Y22: 580056 | Z22: 579981 | AA22: 579783 | AB22: 579425 | AC22: 577838 | AD22: 576107
A23: 12 | B23: 545692 | C23: =+B23/B26 -> 0.20146421 | D23: 545115 | E23: 544529 | F23: 543927 | G23: 543328 | H23: 542650 | I23: 543556 | J23: 544447 | K23: 545319 | L23: 546147 | M23: 546983 | N23: 550529 | O23: 554013 | P23: 557428 | Q23: 560758 | R23: 564028 | S23: 567108 | T23: 570082 | U23: 572945 | V23: 575696 | W23: 578325 | X23: 578990 | Y23: 579521 | Z23: 579918 | AA23: 580189 | AB23: 580301 | AC23: 578943 | AD23: 577441
A24: 13 | B24: 538813 | C24: =+B24/B26 -> 0.19892455 | D24: 539751 | E24: 540681 | F24: 541596 | G24: 542514 | H24: 543352 | I24: 543753 | J24: 544138 | K24: 544504 | L24: 544827 | M24: 545157 | N24: 548313 | O24: 551406 | P24: 554431 | Q24: 557372 | R24: 560254 | S24: 563610 | T24: 566860 | U24: 570001 | V24: 573030 | W24: 575938 | X24: 577123 | Y24: 578176 | Z24: 579095 | AA24: 579889 | AB24: 580522 | AC24: 579496 | AD24: 578326
A25: 14 | B25: 528621 | C25: =+B25/B26 -> 0.19516176 | D25: 531810 | E25: 534990 | F25: 538156 | G25: 541324 | H25: 544415 | I25: 544384 | J25: 544341 | K25: 544277 | L25: 544171 | M25: 544072 | N25: 546654 | O25: 549172 | P25: 551623 | Q25: 553990 | R25: 556300 | S25: 559822 | T25: 563239 | U25: 566547 | V25: 569744 | W25: 572820 | X25: 574550 | Y25: 576148 | Z25: 577614 | AA25: 578954 | AB25: 580133 | AC25: 579518 | AD25: 578758
A26: 15-19 | B26: =SUM(B21:B25) -> 2708630 | D26: 0 | E26: 0 | F26: 0 | G26: 0 | H26: 0 | I26: 0 | J26: 0 | K26: 0 | L26: 0 | M26: 0 | N26: 0 | O26: 0 | P26: 0 | Q26: 0 | R26: 0 | S26: 0 | T26: 0 | U26: 0 | V26: 0 | W26: 0 | X26: 0 | Y26: 0 | Z26: 0 | AA26: 0 | AB26: 0 | AC26: 0 | AD26: 0
A27: 15 | B27: 516877 | C27: =+B27/B32 -> 0.2082231 | D27: 522713 | E27: 528544 | F27: 534357 | G27: 540175 | H27: 545914 | I27: 545319 | J27: 544712 | K27: 544081 | L27: 543411 | M27: 542747 | N27: 544765 | O27: 546719 | P27: 548607 | Q27: 550410 | R27: 552162 | S27: 555836 | T27: 559407 | U27: 562868 | V27: 566220 | W27: 569451 | X27: 571718 | Y27: 573856 | Z27: 575861 | AA27: 577740 | AB27: 579458 | AC27: 579268 | AD27: 578934
A28: 16 | B28: 505486 | C28: =+B28/B32 -> 0.20363426 | D28: 513668 | E28: 521842 | F28: 530002 | G28: 538165 | H28: 546247 | I28: 545285 | J28: 544307 | K28: 543310 | L28: 542269 | M28: 541236 | N28: 542768 | O28: 544237 | P28: 545639 | Q28: 546959 | R28: 548227 | S28: 551994 | T28: 555658 | U28: 559214 | V28: 562661 | W28: 565986 | X28: 568738 | Y28: 571361 | Z28: 573852 | AA28: 576219 | AB28: 578423 | AC28: 578660 | AD28: 578756
A29: 17 | B29: 495009 | C29: =+B29/B32 -> 0.19941361 | D29: 504698 | E29: 514379 | F29: 524047 | G29: 533718 | H29: 543309 | I29: 542788 | J29: 542252 | K29: 541697 | L29: 541098 | M29: 540507 | N29: 541541 | O29: 542512 | P29: 543415 | Q29: 544237 | R29: 545009 | S29: 548656 | T29: 552201 | U29: 555639 | V29: 558968 | W29: 562176 | X29: 565325 | Y29: 568346 | Z29: 571236 | AA29: 574002 | AB29: 576606 | AC29: 577318 | AD29: 577889
A30: 18 | B30: 486282 | C30: =+B30/B32 -> 0.19589796 | D30: 496252 | E30: 506215 | F30: 516165 | G30: 526118 | H30: 535993 | I30: 536984 | J30: 537960 | K30: 538918 | L30: 539832 | M30: 540754 | N30: 541293 | O30: 541769 | P30: 542178 | Q30: 542505 | R30: 542783 | S30: 546048 | T30: 549210 | U30: 552266 | V30: 555214 | W30: 558043 | X30: 561472 | Y30: 564774 | Z30: 567945 | AA30: 570994 | AB30: 573881 | AC30: 575118 | AD30: 576215
A31: 19 | B31: 478669 | C31: =+B31/B32 -> 0.19283107 | D31: 488044 | E31: 497411 | F31: 506765 | G31: 516122 | H31: 525404 | I31: 528635 | J31: 531852 | K31: 535050 | L31: 538206 | M31: 541368 | N31: 541491 | O31: 541550 | P31: 541541 | Q31: 541451 | R31: 541311 | S31: 544010 | T31: 546607 | U31: 549098 | V31: 551482 | W31: 553747 | X31: 557345 | Y31: 560816 | Z31: 564158 | AA31: 567378 | AB31: 570437 | AC31: 572222 | AD31: 573867
A32: 20-24 | B32: =SUM(B27:B31) -> 2482323 | D32: 0 | E32: 0 | F32: 0 | G32: 0 | H32: 0 | I32: 0 | J32: 0 | K32: 0 | L32: 0 | M32: 0 | N32: 0 | O32: 0 | P32: 0 | Q32: 0 | R32: 0 | S32: 0 | T32: 0 | U32: 0 | V32: 0 | W32: 0 | X32: 0 | Y32: 0 | Z32: 0 | AA32: 0 | AB32: 0 | AC32: 0 | AD32: 0
A33: 20 | B33: 471638 | C33: =+B33/B38 -> 0.20926894 | D33: 479983 | E33: 488322 | F33: 496647 | G33: 504976 | H33: 513233 | I33: 519099 | J33: 524955 | K33: 530788 | L33: 536581 | M33: 542381 | N33: 541952 | O33: 541461 | P33: 540902 | Q33: 540260 | R33: 539569 | S33: 541712 | T33: 543755 | U33: 545692 | V33: 547523 | W33: 549237 | X33: 552989 | Y33: 556617 | Z33: 560118 | AA33: 563494 | AB33: 566714 | AC33: 569039 | AD33: 571225
A34: 21 | B34: 463619 | C34: =+B34/B38 -> 0.20571086 | D34: 471203 | E34: 478779 | F34: 486343 | G34: 493909 | H34: 501407 | I34: 509608 | J34: 517796 | K34: 525966 | L34: 534094 | M34: 542229 | N34: 541444 | O34: 540595 | P34: 539678 | Q34: 538681 | R34: 537631 | S34: 539299 | T34: 540864 | U34: 542324 | V34: 543678 | W34: 544918 | X34: 548768 | Y34: 552493 | Z34: 556091 | AA34: 559569 | AB34: 562887 | AC34: 565701 | AD34: 568377
A35: 22 | B35: 453378 | C35: =+B35/B38 -> 0.20116686 | D35: 460845 | E35: 468307 | F35: 475755 | G35: 483206 | H35: 490590 | I35: 500292 | J35: 509981 | K35: 519652 | L35: 529282 | M35: 538919 | N35: 538578 | O35: 538173 | P35: 537702 | Q35: 537149 | R35: 536544 | S35: 537721 | T35: 538796 | U35: 539766 | V35: 540631 | W35: 541383 | X35: 545117 | Y35: 548728 | Z35: 552212 | AA35: 555577 | AB35: 558784 | AC35: 561996 | AD35: 565073
A36: 23 | B36: 440119 | C36: =+B36/B38 -> 0.19528375 | D36: 448452 | E36: 456778 | F36: 465091 | G36: 473408 | H36: 481657 | I36: 491640 | J36: 501610 | K36: 511563 | L36: 521475 | M36: 531393 | N36: 532553 | O36: 533650 | P36: 534682 | Q36: 535633 | R36: 536531 | S36: 537221 | T36: 537809 | U36: 538292 | V36: 538670 | W36: 538935 | X36: 542292 | Y36: 545526 | Z36: 548633 | AA36: 551623 | AB36: 554456 | AC36: 557949 | AD36: 561307
A37: 24 | B37: 424987 | C37: =+B37/B38 -> 0.18856958 | D37: 434804 | E37: 444615 | F37: 454414 | G37: 464215 | H37: 473949 | I37: 483339 | J37: 492716 | K37: 502077 | L37: 511397 | M37: 520722 | N37: 524102 | O37: 527421 | P37: 530675 | Q37: 533849 | R37: 536970 | S37: 537249 | T37: 537426 | U37: 537497 | V37: 537465 | W37: 537319 | X37: 540115 | Y37: 542789 | Z37: 545337 | AA37: 547768 | AB37: 550043 | AC37: 553704 | AD37: 557232
A38: 25-29 | B38: =SUM(B33:B37) -> 2253741 | D38: 0 | E38: 0 | F38: 0 | G38: 0 | H38: 0 | I38: 0 | J38: 0 | K38: 0 | L38: 0 | M38: 0 | N38: 0 | O38: 0 | P38: 0 | Q38: 0 | R38: 0 | S38: 0 | T38: 0 | U38: 0 | V38: 0 | W38: 0 | X38: 0 | Y38: 0 | Z38: 0 | AA38: 0 | AB38: 0 | AC38: 0 | AD38: 0
A39: 25 | B39: 408834 | C39: =+B39/B44 -> 0.21089604 | D39: 420461 | E39: 432083 | F39: 443694 | G39: 455307 | H39: 466850 | I39: 475218 | J39: 483573 | K39: 491911 | L39: 500209 | M39: 508512 | N39: 514503 | O39: 520435 | P39: 526305 | Q39: 532094 | R39: 537829 | S39: 537564 | T39: 537197 | U39: 536724 | V39: 536148 | W39: 535458 | X39: 537703 | Y39: 539827 | Z39: 541826 | AA39: 543708 | AB39: 545438 | AC39: 549252 | AD39: 552935
A40: 26 | B40: 394149 | C40: =+B40/B44 -> 0.20332082 | D40: 407098 | E40: 420043 | F40: 432976 | G40: 445912 | H40: 458778 | I40: 466387 | J40: 473984 | K40: 481564 | L40: 489106 | M40: 496650 | N40: 504952 | O40: 513199 | P40: 521382 | Q40: 529486 | R40: 537538 | S40: 536921 | T40: 536201 | U40: 535376 | V40: 534448 | W40: 533406 | X40: 535179 | Y40: 536830 | Z40: 538356 | AA40: 539766 | AB40: 541024 | AC40: 544936 | AD40: 548716
A41: 27 | B41: 383146 | C41: =+B41/B44 -> 0.19764495 | D41: 396252 | E41: 409352 | F41: 422441 | G41: 435533 | H41: 448556 | I41: 456046 | J41: 463524 | K41: 470986 | L41: 478411 | M41: 485837 | N41: 495625 | O41: 505358 | P41: 515030 | Q41: 524622 | R41: 534163 | S41: 533986 | T41: 533708 | U41: 533325 | V41: 532839 | W41: 532239 | X41: 533525 | Y41: 534689 | Z41: 535729 | AA41: 536653 | AB41: 537427 | AC41: 541223 | AD41: 544888
A42: 28 | B42: 377276 | C42: =+B42/B44 -> 0.19461692 | D42: 388923 | E42: 400565 | F42: 412196 | G42: 423830 | H42: 435396 | I42: 443738 | J42: 452069 | K42: 460385 | L42: 468663 | M42: 476944 | N42: 487007 | O42: 497016 | P42: 506966 | Q42: 516837 | R42: 526656 | S42: 527967 | T42: 529177 | U42: 530285 | V42: 531290 | W42: 532178 | X42: 532980 | Y42: 533660 | Z42: 534216 | AA42: 534657 | AB42: 534948 | AC42: 538368 | AD42: 541659
...

Sheet Mortalidad
A1: Fuente: Portal_MPPS http://www.mpps.gob.ve/index.php?option=com_phocadownload&view=category&id=11:anuarios-de-mortalidad
A2: Año | B2: C | C2: Total | D2: -1 | E2: 1 | F2: 2 | G2: 3 | H2: 4 | I2: 5 a 9 | J2: 10 a 14 | K2: 15 a 19 | L2: 20 a 24 | M2: 25 a 29 | N2: 30 a 34 | O2: 35 a 39 | P2: 40 a 44 | Q2: 45 a 49 | R2: 50 a 54 | S2: 55 a 59 | T2: 60 a 64 | U2: 65 a 69 | V2: 70 a 74 | W2: 75 a 79 | X2: 80 a 84 | Y2: 85 y + | Z2: O
A3: 2011 | B3: T | C3: 143020 | D3: 8900 | E3: 607 | F3: 356 | G3: 244 | H3: 188 | I3: 687 | J3: 969 | K3: 4526 | L3: 6425 | M3: 5627 | N3: 4867 | O3: 4482 | P3: 4705 | Q3: 5771 | R3: 7612 | S3: 9215 | T3: 10405 | U3: 10481 | V3: 11607 | W3: 12602 | X3: 13334 | Y3: 19336 | Z3: 74
A4: 2011 | B4: V | C4: 86504 | D4: 5033 | E4: 310 | F4: 192 | G4: 138 | H4: 95 | I4: 401 | J4: 596 | K4: 3845 | L4: 5635 | M4: 4683 | N4: 3726 | O4: 3216 | P4: 3109 | Q4: 3747 | R4: 4804 | S4: 5861 | T4: 6450 | U4: 6414 | V4: 6767 | W4: 6805 | X4: 6649 | Y4: 7960 | Z4: 68
A5: 2011 | B5: H | C5: 56516 | D5: 3867 | E5: 297 | F5: 164 | G5: 106 | H5: 93 | I5: 286 | J5: 373 | K5: 681 | L5: 790 | M5: 944 | N5: 1141 | O5: 1266 | P5: 1596 | Q5: 2024 | R5: 2808 | S5: 3354 | T5: 3955 | U5: 4067 | V5: 4840 | W5: 5797 | X5: 6685 | Y5: 11376 | Z5: 6
A6: =+A3-1 -> 2010 | B6: T | C6: 138504 | D6: 8965 | E6: 640 | F6: 365 | G6: 233 | H6: 215 | I6: 784 | J6: 939 | K6: 4584 | L6: 6388 | M6: 5735 | N6: 4897 | O6: 4295 | P6: 4582 | Q6: 5757 | R6: 7287 | S6: 8799 | T6: 9656 | U6: 9872 | V6: 11445 | W6: 12236 | X6: 12775 | Y6: 18019 | Z6: 36
A7: =+A4-1 -> 2010 | B7: V | C7: 84196 | D7: 5102 | E7: 350 | F7: 227 | G7: 145 | H7: 111 | I7: 449 | J7: 598 | K7: 3822 | L7: 5535 | M7: 4783 | N7: 3810 | O7: 3070 | P7: 3034 | Q7: 3757 | R7: 4687 | S7: 5517 | T7: 6044 | U7: 5919 | V7: 6536 | W7: 6742 | X7: 6449 | Y7: 7476 | Z7: 33
A8: =+A5-1 -> 2010 | B8: H | C8: 54308 | D8: 3863 | E8: 290 | F8: 138 | G8: 88 | H8: 104 | I8: 335 | J8: 341 | K8: 762 | L8: 853 | M8: 952 | N8: 1087 | O8: 1225 | P8: 1548 | Q8: 2000 | R8: 2600 | S8: 3282 | T8: 3612 | U8: 3953 | V8: 4909 | W8: 5494 | X8: 6326 | Y8: 10543 | Z8: 3
A9: =+A6-1 -> 2009 | B9: T | C9: 134731 | D9: 8577 | E9: 654 | F9: 360 | G9: 246 | H9: 204 | I9: 766 | J9: 966 | K9: 4813 | L9: 6958 | M9: 6119 | N9: 5049 | O9: 4377 | P9: 4899 | Q9: 5937 | R9: 7266 | S9: 8663 | T9: 9084 | U9: 9477 | V9: 10717 | W9: 11884 | X9: 11527 | Y9: 16100 | Z9: 88
A10: =+A7-1 -> 2009 | B10: V | C10: 83325 | D10: 4888 | E10: 346 | F10: 184 | G10: 133 | H10: 125 | I10: 439 | J10: 612 | K10: 4051 | L10: 6103 | M10: 5096 | N10: 4023 | O10: 3207 | P10: 3357 | Q10: 3858 | R10: 4729 | S10: 5524 | T10: 5663 | U10: 5751 | V10: 6201 | W10: 6628 | X10: 5706 | Y10: 6622 | Z10: 79
A11: =+A8-1 -> 2009 | B11: H | C11: 51406 | D11: 3689 | E11: 308 | F11: 176 | G11: 113 | H11: 79 | I11: 327 | J11: 354 | K11: 762 | L11: 855 | M11: 1023 | N11: 1026 | O11: 1170 | P11: 1542 | Q11: 2079 | R11: 2537 | S11: 3139 | T11: 3421 | U11: 3726 | V11: 4516 | W11: 5256 | X11: 5821 | Y11: 9478 | Z11: 9
A12: =+A9-1 -> 2008 | B12: T | C12: 133651 | D12: 8307 | E12: 662 | F12: 329 | G12: 254 | H12: 168 | I12: 733 | J12: 1060 | K12: 4840 | L12: 7108 | M12: 6077 | N12: 4933 | O12: 4403 | P12: 4813 | Q12: 5847 | R12: 7046 | S12: 8392 | T12: 8603 | U12: 9514 | V12: 10668 | W12: 12014 | X12: 11380 | Y12: 16292 | Z12: 208
A13: =+A10-1 -> 2008 | B13: V | C13: 83106 | D13: 4781 | E13: 369 | F13: 180 | G13: 149 | H13: 88 | I13: 432 | J13: 671 | K13: 4087 | L13: 6239 | M13: 5161 | N13: 3943 | O13: 3245 | P13: 3326 | Q13: 3837 | R13: 4585 | S13: 5279 | T13: 5377 | U13: 5771 | V13: 6222 | W13: 6676 | X13: 5749 | Y13: 6749 | Z13: 190
A14: =+A11-1 -> 2008 | B14: H | C14: 50545 | D14: 3526 | E14: 293 | F14: 149 | G14: 105 | H14: 80 | I14: 301 | J14: 389 | K14: 753 | L14: 869 | M14: 916 | N14: 990 | O14: 1158 | P14: 1487 | Q14: 2010 | R14: 2461 | S14: 3113 | T14: 3226 | U14: 3743 | V14: 4446 | W14: 5338 | X14: 5631 | Y14: 9543 | Z14: 18
A15: =+A12-1 -> 2007 | B15: T | C15: 127463 | D15: 8323 | E15: 800 | F15: 371 | G15: 252 | H15: 203 | I15: 828 | J15: 1058 | K15: 4355 | L15: 6472 | M15: 5905 | N15: 4683 | O15: 4345 | P15: 4682 | Q15: 5754 | R15: 6824 | S15: 7738 | T15: 8154 | U15: 9148 | V15: 10436 | W15: 11455 | X15: 10501 | Y15: 15010 | Z15: 166
A16: =+A13-1 -> 2007 | B16: V | C16: 79156 | D16: 4847 | E16: 436 | F16: 206 | G16: 137 | H16: 123 | I16: 519 | J16: 667 | K16: 3665 | L16: 5680 | M16: 5029 | N16: 3701 | O16: 3193 | P16: 3249 | Q16: 3747 | R16: 4366 | S16: 4959 | T16: 5094 | U16: 5574 | V16: 6045 | W16: 6255 | X16: 5305 | Y16: 6229 | Z16: 130
A17: =+A14-1 -> 2007 | B17: H | C17: 48307 | D17: 3476 | E17: 364 | F17: 165 | G17: 115 | H17: 80 | I17: 309 | J17: 391 | K17: 690 | L17: 792 | M17: 876 | N17: 982 | O17: 1152 | P17: 1433 | Q17: 2007 | R17: 2458 | S17: 2779 | T17: 3060 | U17: 3574 | V17: 4391 | W17: 5200 | X17: 5196 | Y17: 8781 | Z17: 36
... A53: =+A50-1 -> 1995 | B53: H | C53: 40996 | D53: 5291 | E53: 637 | F53: 249 | G53: 157 | H53: 98 | I53: 419 | J53: 416 | K53: 647 | L53: 671 | M53: 708 | N53: 836 | O53: 1035 | P53: 1288 | Q53: 1476 | R53: 1564 | S53: 2120 | T53: 2581 | U53: 3306 | V53: 3673 | W53: 3813 | X53: 4085 | Y53: 5856 | Z53: 70

Sheet Mortalidad M
A1: Fuente: Portal_MPPS http://www.mpps.gob.ve/index.php?option=com_phocadownload&view=category&id=11:anuarios-de-mortalidad
A2: Año | B2: C | C2: Total | D2: -1 | E2: 1 | F2: 2 | G2: 3 | H2: 4 | I2: 5 a 9 | J2: 10 a 14 | K2: 15 a 19 | L2: 20 a 24 | M2: 25 a 29 | N2: 30 a 34 | O2: 35 a 39 | P2: 40 a 44 | Q2: 45 a 49 | R2: 50 a 54 | S2: 55 a 59 | T2: 60 a 64 | U2: 65 a 69 | V2: 70 a 74 | W2: 75 a 79 | X2: 80 a 84 | Y2: 85 y + | Z2: O
A3: 1995 | B3: V | C3: 57140 | D3: 7061 | E3: 700 | F3: 276 | G3: 190 | H3: 140 | I3: 570 | J3: 670 | K3: 2137 | L3: 2788 | M3: 2426 | N3: 2300 | O3: 2193 | P3: 2226 | Q3: 2251 | R3: 2631 | S3: 3106 | T3: 3960 | U3: 4445 | V3: 4574 | W3: 4350 | X3: 3869 | Y3: 4084 | Z3: 193
A4: 1996 | B4: V | C4: 58207 | D4: 6830 | E4: 829 | F4: 359 | G4: 220 | H4: 178 | I4: 632 | J4: 654 | K4: 2130 | L4: 2666 | M4: 2466 | N4: 2170 | O4: 2125 | P4: 2242 | Q4: 2438 | R4: 2668 | S4: 3199 | T4: 3910 | U4: 4794 | V4: 4850 | W4: 4580 | X4: 3880 | Y4: 4342 | Z4: 45
A5: 1997 | B5: V | C5: 56598 | D5: 6324 | E5: 640 | F5: 293 | G5: 187 | H5: 145 | I5: 614 | J5: 647 | K5: 1884 | L5: 2476 | M5: 2274 | N5: 2090 | O5: 2130 | P5: 2302 | Q5: 2448 | R5: 2721 | S5: 3147 | T5: 3864 | U5: 4643 | V5: 4978 | W5: 4778 | X5: 3710 | Y5: 4186 | Z5: 117
A6: 1998 | B6: V | C6: 59449 | D6: 6144 | E6: 765 | F6: 305 | G6: 199 | H6: 164 | I6: 575 | J6: 638 | K6: 1875 | L6: 2721 | M6: 2380 | N6: 2253 | O6: 2270 | P6: 2533 | Q6: 2792 | R6: 2932 | S6: 3435 | T6: 4075 | U6: 4839 | V6: 5168 | W6: 4741 | X6: 3900 | Y6: 4557 | Z6: 188
A7: 1999 | B7: V | C7: 61503 | D7: 5835 | E7: 641 | F7: 298 | G7: 183 | H7: 156 | I7: 626 | J7: 616 | K7: 2162 | L7: 3141 | M7: 2830 | N7: 2502 | O7: 2399 | P7: 2572 | Q7: 2941 | R7: 3077 | S7: 3415 | T7: 4270 | U7: 4976 | V7: 5171 | W7: 4947 | X7: 4107 | Y7: 4532 | Z7: 106
A8: 2000 | B8: V | C8: 64101 | D8: 5622 | E8: 639 | F8: 273 | G8: 174 | H8: 138 | I8: 588 | J8: 603 | K8: 2643 | L8: 4041 | M8: 3300 | N8: 2865 | O8: 2626 | P8: 2806 | Q8: 3047 | R8: 3301 | S8: 3432 | T8: 4090 | U8: 4735 | V8: 5542 | W8: 4863 | X8: 4120 | Y8: 4555 | Z8: 98
A9: 2001 | B9: V | C9: 66616 | D9: 5375 | E9: 662 | F9: 298 | G9: 185 | H9: 138 | I9: 536 | J9: 635 | K9: 2699 | L9: 4132 | M9: 3438 | N9: 2829 | O9: 2794 | P9: 2911 | Q9: 3371 | R9: 3624 | S9: 3652 | T9: 4280 | U9: 4962 | V9: 5649 | W9: 5092 | X9: 4340 | Y9: 4938 | Z9: 76
A10: 2002 | B10: V | C10: 65573 | D10: 4976 | E10: 599 | F10: 251 | G10: 143 | H10: 139 | I10: 509 | J10: 682 | K10: 3007 | L10: 4658 | M10: 3573 | N10: 2802 | O10: 2526 | P10: 2786 | Q10: 3222 | R10: 3651 | S10: 3761 | T10: 4062 | U10: 4725 | V10: 5389 | W10: 5047 | X10: 4149 | Y10: 4833 | Z10: 83
A11: 2003 | B11: V | C11: 73826 | D11: 5848 | E11: 825 | F11: 308 | G11: 179 | H11: 121 | I11: 543 | J11: 693 | K11: 3402 | L11: 5314 | M11: 4242 | N11: 3242 | O11: 2983 | P11: 3038 | Q11: 3400 | R11: 3804 | S11: 4070 | T11: 4574 | U11: 5273 | V11: 5827 | W11: 5741 | X11: 4801 | Y11: 5564 | Z11: 34
A12: 2004 | B12: V | C12: 70835 | D12: 5317 | E12: 553 | F12: 267 | G12: 163 | H12: 125 | I12: 572 | J12: 641 | K12: 3036 | L12: 4648 | M12: 3908 | N12: 3112 | O12: 2785 | P12: 2888 | Q12: 3356 | R12: 3906 | S12: 4173 | T12: 4511 | U12: 5062 | V12: 5603 | W12: 5835 | X12: 4751 | Y12: 5552 | Z12: 71
A13: 2005 | B13: V | C13: 71155 | D13: 5204 | E13: 476 | F13: 208 | G13: 123 | H13: 126 | I13: 495 | J13: 632 | K13: 2927 | L13: 4391 | M13: 3859 | N13: 3018 | O13: 2705 | P13: 3020 | Q13: 3424 | R13: 4027 | S13: 4356 | T13: 4646 | U13: 5140 | V13: 5557 | W13: 6016 | X13: 4881 | Y13: 5832 | Z13: 92
A14: 2006 | B14: V | C14: 74378 | D14: 4801 | E14: 430 | F14: 231 | G14: 136 | H14: 114 | I14: 491 | J14: 655 | K14: 3255 | L14: 5060 | M14: 4458 | N14: 3237 | O14: 2857 | P14: 3144 | Q14: 3648 | R14: 4239 | S14: 4730 | T14: 4683 | U14: 5259 | V14: 5832 | W14: 6091 | X14: 5041 | Y14: 5957 | Z14: 29
... A19: 2011 | B19: V | C19: 86504 | D19: 5033 | E19: 310 | F19: 192 | G19: 138 | H19: 95 | I19: 401 | J19: 596 | K19: 3845 | L19: 5635 | M19: 4683 | N19: 3726 | O19: 3216 | P19: 3109 | Q19: 3747 | R19: 4804 | S19: 5861 | T19: 6450 | U19: 6414 | V19: 6767 | W19: 6805 | X19: 6649 | Y19: 7960 | Z19: 68
A22: Año | B22: C | C22: 0 a 4 | D22: =+I2 -> 5 a 9 | E22: =+J2 -> 10 a 14 | F22: =+K2 -> 15 a 19 | G22: =+L2 -> 20 a 24 | H22: =+M2 -> 25 a 29 | I22: =+N2 -> 30 a 34 | J22: =+O2 -> 35 a 39 | K22: =+P2 -> 40 a 44 | ... U22: =+Z2 -> O | V22: Total
A23: 1995 | B23: V | C23: =+SUM(D3:H3) -> 8367 | D23: =+I3 -> 570 | E23: =+J3 -> 670 | F23: =+K3 -> 2137 | G23: =+L3 -> 2788 | H23: =+M3 -> 2426 | I23: =+N3 -> 2300 | J23: =+O3 -> 2193 | K23: =+P3 -> 2226 | ... U23: =+Z3 -> 193 | V23: =SUM(C23:U23) -> 57140
A24: 1996 | B24: V | C24: =+SUM(D4:H4) -> 8416 | D24: =+I4 -> 632 | E24: =+J4 -> 654 | F24: =+K4 -> 2130 | G24: =+L4 -> 2666 | H24: =+M4 -> 2466 | I24: =+N4 -> 2170 | J24: =+O4 -> 2125 | K24: =+P4 -> 2242 | ... U24: =+Z4 -> 45 | V24: =SUM(C24:U24) -> 58207
A25: 1997 | B25: V | C25: =+SUM(D5:H5) -> 7589 | D25: =+I5 -> 614 | E25: =+J5 -> 647 | F25: =+K5 -> 1884 | G25: =+L5 -> 2476 | H25: =+M5 -> 2274 | I25: =+N5 -> 2090 | J25: =+O5 -> 2130 | K25: =+P5 -> 2302 | ... U25: =+Z5 -> 117 | V25: =SUM(C25:U25) -> 56598
A26: 1998 | B26: V | C26: =+SUM(D6:H6) -> 7577 | D26: =+I6 -> 575 | E26: =+J6 -> 638 | F26: =+K6 -> 1875 | G26: =+L6 -> 2721 | H26: =+M6 -> 2380 | I26: =+N6 -> 2253 | J26: =+O6 -> 2270 | K26: =+P6 -> 2533 | ... U26: =+Z6 -> 188 | V26: =SUM(C26:U26) -> 59449
A27: 1999 | B27: V | C27: =+SUM(D7:H7) -> 7113 | D27: =+I7 -> 626 | E27: =+J7 -> 616 | F27: =+K7 -> 2162 | G27: =+L7 -> 3141 | H27: =+M7 -> 2830 | I27: =+N7 -> 2502 | J27: =+O7 -> 2399 | K27: =+P7 -> 2572 | ... U27: =+Z7 -> 106 | V27: =SUM(C27:U27) -> 61503
A28: 2000 | B28: V | C28: =+SUM(D8:H8) -> 6846 | D28: =+I8 -> 588 | E28: =+J8 -> 603 | F28: =+K8 -> 2643 | G28: =+L8 -> 4041 | H28: =+M8 -> 3300 | I28: =+N8 -> 2865 | J28: =+O8 -> 2626 | K28: =+P8 -> 2806 | ... U28: =+Z8 -> 98 | V28: =SUM(C28:U28) -> 64101
A29: 2001 | B29: V | C29: =+SUM(D9:H9) -> 6658 | D29: =+I9 -> 536 | E29: =+J9 -> 635 | F29: =+K9 -> 2699 | G29: =+L9 -> 4132 | H29: =+M9 -> 3438 | I29: =+N9 -> 2829 | J29: =+O9 -> 2794 | K29: =+P9 -> 2911 | ... U29: =+Z9 -> 76 | V29: =SUM(C29:U29) -> 66616
A30: 2002 | B30: V | C30: =+SUM(D10:H10) -> 6108 | D30: =+I10 -> 509 | E30: =+J10 -> 682 | F30: =+K10 -> 3007 | G30: =+L10 -> 4658 | H30: =+M10 -> 3573 | I30: =+N10 -> 2802 | J30: =+O10 -> 2526 | K30: =+P10 -> 2786 | ... U30: =+Z10 -> 83 | V30: =SUM(C30:U30) -> 65573
A31: 2003 | B31: V | C31: =+SUM(D11:H11) -> 7281 | D31: =+I11 -> 543 | E31: =+J11 -> 693 | F31: =+K11 -> 3402 | G31: =+L11 -> 5314 | H31: =+M11 -> 4242 | I31: =+N11 -> 3242 | J31: =+O11 -> 2983 | K31: =+P11 -> 3038 | ... U31: =+Z11 -> 34 | V31: =SUM(C31:U31) -> 73826
A32: 2004 | B32: V | C32: =+SUM(D12:H12) -> 6425 | D32: =+I12 -> 572 | E32: =+J12 -> 641 | F32: =+K12 -> 3036 | G32: =+L12 -> 4648 | H32: =+M12 -> 3908 | I32: =+N12 -> 3112 | J32: =+O12 -> 2785 | K32: =+P12 -> 2888 | ... U32: =+Z12 -> 71 | V32: =SUM(C32:U32) -> 70835
A33: 2005 | B33: V | C33: =+SUM(D13:H13) -> 6137 | D33: =+I13 -> 495 | E33: =+J13 -> 632 | F33: =+K13 -> 2927 | G33: =+L13 -> 4391 | H33: =+M13 -> 3859 | I33: =+N13 -> 3018 | J33: =+O13 -> 2705 | K33: =+P13 -> 3020 | ... U33: =+Z13 -> 92 | V33: =SUM(C33:U33) -> 71155
A34: 2006 | B34: V | C34: =+SUM(D14:H14) -> 5712 | D34: =+I14 -> 491 | E34: =+J14 -> 655 | F34: =+K14 -> 3255 | G34: =+L14 -> 5060 | H34: =+M14 -> 4458 | I34: =+N14 -> 3237 | J34: =+O14 -> 2857 | K34: =+P14 -> 3144 | ... U34: =+Z14 -> 29 | V34: =SUM(C34:U34) -> 74378
... A39: 2011 | B39: V | C39: =+SUM(D19:H19) -> 5768 | D39: =+I19 -> 401 | E39: =+J19 -> 596 | F39: =+K19 -> 3845 | G39: =+L19 -> 5635 | H39: =+M19 -> 4683 | I39: =+N19 -> 3726 | J39: =+O19 -> 3216 | K39: =+P19 -> 3109 | ... U39: =+Z19 -> 68 | V39: =SUM(C39:U39) -> 86504
C41: Año | D41: 1995 | E41: 1996 | F41: 1997 | G41: 1998 | H41: 1999 | I41: 2000 | J41: 2001 | K41: 2002 | L41: 2003 | M41: 2004 | N41: 2005 | O41: 2006 | P41: 2007 | Q41: 2008 | R41: 2009 | S41: 2010 | T41: 2011
C42: -1 | D42: 7061 | E42: 6830 | F42: 6324 | G42: 6144 | H42: 5835 | I42: 5622 | J42: 5375 | K42: 4976 | L42: 5848 | M42: 5317 | N42: 5204 | O42: 4801 | P42: 4847 | Q42: 4781 | R42: 4888 | S42: 5102 | T42: 5033
C43: 1 | D43: 700 | E43: 829 | F43: 640 | G43: 765 | H43: 641 | I43: 639 | J43: 662 | K43: 599 | L43: 825 | M43: 553 | N43: 476 | O43: 430 | P43: 436 | Q43: 369 | R43: 346 | S43: 350 | T43: 310
C44: 2 | D44: 276 | E44: 359 | F44: 293 | G44: 305 | H44: 298 | I44: 273 | J44: 298 | K44: 251 | L44: 308 | M44: 267 | N44: 208 | O44: 231 | P44: 206 | Q44: 180 | R44: 184 | S44: 227 | T44: 192
C45: 3 | D45: 190 | E45: 220 | F45: 187 | G45: 199 | H45: 183 | I45: 174 | J45: 185 | K45: 143 | L45: 179 | M45: 163 | N45: 123 | O45: 136 | P45: 137 | Q45: 149 | R45: 133 | S45: 145 | T45: 138
C46: 4 | D46: 140 | E46: 178 | F46: 145 | G46: 164 | H46: 156 | I46: 138 | J46: 138 | K46: 139 | L46: 121 | M46: 125 | N46: 126 | O46: 114 | P46: 123 | Q46: 88 | R46: 125 | S46: 111 | T46: 95

Sheet Mortalidad F
A1: Fuente: Portal_MPPS http://www.mpps.gob.ve/index.php?option=com_phocadownload&view=category&id=11:anuarios-de-mortalidad
A2: Año | B2: C | C2: Total | D2: -1 | E2: 1 | F2: 2 | G2: 3 | H2: 4 | I2: 5 a 9 | J2: 10 a 14 | K2: 15 a 19 | L2: 20 a 24 | M2: 25 a 29 | N2: 30 a 34 | O2: 35 a 39 | P2: 40 a 44 | Q2: 45 a 49 | R2: 50 a 54 | S2: 55 a 59 | T2: 60 a 64 | U2: 65 a 69 | V2: 70 a 74 | W2: 75 a 79 | X2: 80 a 84 | Y2: 85 y + | Z2: O
A3: 1995 | B3: H | C3: 40996 | D3: 5291 | E3: 637 | F3: 249 | G3: 157 | H3: 98 | I3: 419 | J3: 416 | K3: 647 | L3: 671 | M3: 708 | N3: 836 | O3: 1035 | P3: 1288 | Q3: 1476 | R3: 1564 | S3: 2120 | T3: 2581 | U3: 3306 | V3: 3673 | W3: 3813 | X3: 4085 | Y3: 5856 | Z3: 70
A4: 1996 | B4: H | C4: 41838 | D4: 5083 | E4: 740 | F4: 279 | G4: 162 | H4: 129 | I4: 426 | J4: 414 | K4: 674 | L4: 676 | M4: 767 | N4: 919 | O4: 1098 | P4: 1295 | Q4: 1484 | R4: 1701 | S4: 2110 | T4: 2593 | U4: 3399 | V4: 3620 | W4: 4131 | X4: 4144 | Y4: 5962 | Z4: 32
A5: 1997 | B5: H | C5: 41413 | D5: 4745 | E5: 582 | F5: 256 | G5: 158 | H5: 130 | I5: 399 | J5: 405 | K5: 619 | L5: 694 | M5: 748 | N5: 853 | O5: 1147 | P5: 1432 | Q5: 1550 | R5: 1719 | S5: 2046 | T5: 2679 | U5: 3319 | V5: 3719 | W5: 3974 | X5: 4035 | Y5: 6170 | Z5: 34
A6: 1998 | B6: H | C6: 41514 | D6: 4577 | E6: 608 | F6: 255 | G6: 162 | H6: 108 | I6: 406 | J6: 407 | K6: 591 | L6: 667 | M6: 750 | N6: 816 | O6: 1103 | P6: 1312 | Q6: 1649 | R6: 1770 | S6: 2070 | T6: 2611 | U6: 3475 | V6: 3898 | W6: 4171 | X6: 3974 | Y6: 6078 | Z6: 56
A7: 1999 | B7: H | C7: 43122 | D7: 4273 | E7: 564 | F7: 229 | G7: 163 | H7: 119 | I7: 416 | J7: 387 | K7: 642 | L7: 734 | M7: 745 | N7: 863 | O7: 1086 | P7: 1386 | Q7: 1727 | R7: 1853 | S7: 2187 | T7: 2785 | U7: 3451 | V7: 4116 | W7: 4401 | X7: 4351 | Y7: 6617 | Z7: 27
A8: 2000 | B8: H | C8: 41847 | D8: 4027 | E8: 568 | F8: 220 | G8: 144 | H8: 102 | I8: 398 | J8: 363 | K8: 655 | L8: 701 | M8: 742 | N8: 864 | O8: 1083 | P8: 1374 | Q8: 1687 | R8: 1948 | S8: 2043 | T8: 2793 | U8: 3317 | V8: 4041 | W8: 4205 | X8: 4260 | Y8: 6293 | Z8: 19
A9: 2001 | B9: H | C9: 44056 | D9: 3978 | E9: 581 | F9: 235 | G9: 127 | H9: 112 | I9: 438 | J9: 422 | K9: 651 | L9: 728 | M9: 796 | N9: 898 | O9: 1103 | P9: 1467 | Q9: 1779 | R9: 2029 | S9: 2104 | T9: 2796 | U9: 3391 | V9: 4308 | W9: 4531 | X9: 4535 | Y9: 7044 | Z9: 3
A10: 2002 | B10: H | C10: 44720 | D10: 3973 | E10: 545 | F10: 187 | G10: 139 | H10: 111 | I10: 368 | J10: 422 | K10: 762 | L10: 921 | M10: 950 | N10: 974 | O10: 1180 | P10: 1519 | Q10: 1921 | R10: 2200 | S10: 2351 | T10: 2738 | U10: 3546 | V10: 4135 | W10: 4575 | X10: 4301 | Y10: 6890 | Z10: 12
A11: 2003 | B11: H | C11: 48038 | D11: 4428 | E11: 714 | F11: 282 | G11: 176 | H11: 108 | I11: 378 | J11: 423 | K11: 702 | L11: 876 | M11: 896 | N11: 957 | O11: 1144 | P11: 1492 | Q11: 1877 | R11: 2345 | S11: 2474 | T11: 2828 | U11: 3662 | V11: 4429 | W11: 4997 | X11: 4832 | Y11: 8014 | Z11: 4
A12: 2004 | B12: H | C12: 46392 | D12: 3955 | E12: 501 | F12: 208 | G12: 144 | H12: 124 | I12: 370 | J12: 425 | K12: 712 | L12: 821 | M12: 846 | N12: 899 | O12: 1077 | P12: 1427 | Q12: 1875 | R12: 2259 | S12: 2473 | T12: 2719 | U12: 3548 | V12: 4311 | W12: 4980 | X12: 4884 | Y12: 7824 | Z12: 10
A13: 2005 | B13: H | C13: 46676 | D13: 3889 | E13: 402 | F13: 171 | G13: 107 | H13: 82 | I13: 339 | J13: 347 | K13: 645 | L13: 814 | M13: 835 | N13: 872 | O13: 1109 | P13: 1420 | Q13: 1851 | R13: 2358 | S13: 2676 | T13: 2881 | U13: 3567 | V13: 4182 | W13: 5117 | X13: 4897 | Y13: 8102 | Z13: 13
A14: 2006 | B14: H | C14: 47208 | D14: 3570 | E14: 391 | F14: 148 | G14: 101 | H14: 99 | I14: 351 | J14: 413 | K14: 710 | L14: 760 | M14: 900 | N14: 952 | O14: 1084 | P14: 1504 | Q14: 1965 | R14: 2459 | S14: 2697 | T14: 2935 | U14: 3522 | V14: 4198 | W14: 4963 | X14: 5114 | Y14: 8365 | Z14: 7
... A19: 2011 | B19: H | C19: 56516 | D19: 3867 | E19: 297 | F19: 164 | G19: 106 | H19: 93 | I19: 286 | J19: 373 | K19: 681 | L19: 790 | M19: 944 | N19: 1141 | O19: 1266 | P19: 1596 | Q19: 2024 | R19: 2808 | S19: 3354 | T19: 3955 | U19: 4067 | V19: 4840 | W19: 5797 | X19: 6685 | Y19: 11376 | Z19: 6
A22: Año | B22: C | C22: 0 a 4 | D22: =+I2 -> 5 a 9 | E22: =+J2 -> 10 a 14 | F22: =+K2 -> 15 a 19 | G22: =+L2 -> 20 a 24 | H22: =+M2 -> 25 a 29 | I22: =+N2 -> 30 a 34 | J22: =+O2 -> 35 a 39 | K22: =+P2 -> 40 a 44 | ... U22: =+Z2 -> O | V22: Total
A23: 1995 | B23: H | C23: =+SUM(D3:H3) -> 6432 | D23: =+I3 -> 419 | E23: =+J3 -> 416 | F23: =+K3 -> 647 | G23: =+L3 -> 671 | H23: =+M3 -> 708 | I23: =+N3 -> 836 | J23: =+O3 -> 1035 | K23: =+P3 -> 1288 | ... U23: =+Z3 -> 70 | V23: 143020
A24: 1996 | B24: H | C24: =+SUM(D4:H4) -> 6393 | D24: =+I4 -> 426 | E24: =+J4 -> 414 | F24: =+K4 -> 674 | G24: =+L4 -> 676 | H24: =+M4 -> 767 | I24: =+N4 -> 919 | J24: =+O4 -> 1098 | K24: =+P4 -> 1295 | ... U24: =+Z4 -> 32 | V24: 138504
A25: 1997 | B25: H | C25: =+SUM(D5:H5) -> 5871 | D25: =+I5 -> 399 | E25: =+J5 -> 405 | F25: =+K5 -> 619 | G25: =+L5 -> 694 | H25: =+M5 -> 748 | I25: =+N5 -> 853 | J25: =+O5 -> 1147 | K25: =+P5 -> 1432 | ... U25: =+Z5 -> 34 | V25: 134731
A26: 1998 | B26: H | C26: =+SUM(D6:H6) -> 5710 | D26: =+I6 -> 406 | E26: =+J6 -> 407 | F26: =+K6 -> 591 | G26: =+L6 -> 667 | H26: =+M6 -> 750 | I26: =+N6 -> 816 | J26: =+O6 -> 1103 | K26: =+P6 -> 1312 | ... U26: =+Z6 -> 56 | V26: 133651
A27: 1999 | B27: H | C27: =+SUM(D7:H7) -> 5348 | D27: =+I7 -> 416 | E27: =+J7 -> 387 | F27: =+K7 -> 642 | G27: =+L7 -> 734 | H27: =+M7 -> 745 | I27: =+N7 -> 863 | J27: =+O7 -> 1086 | K27: =+P7 -> 1386 | ... U27: =+Z7 -> 27 | V27: 127463
A28: 2000 | B28: H | C28: =+SUM(D8:H8) -> 5061 | D28: =+I8 -> 398 | E28: =+J8 -> 363 | F28: =+K8 -> 655 | G28: =+L8 -> 701 | H28: =+M8 -> 742 | I28: =+N8 -> 864 | J28: =+O8 -> 1083 | K28: =+P8 -> 1374 | ... U28: =+Z8 -> 19 | V28: 121586
A29: 2001 | B29: H | C29: =+SUM(D9:H9) -> 5033 | D29: =+I9 -> 438 | E29: =+J9 -> 422 | F29: =+K9 -> 651 | G29: =+L9 -> 728 | H29: =+M9 -> 796 | I29: =+N9 -> 898 | J29: =+O9 -> 1103 | K29: =+P9 -> 1467 | ... U29: =+Z9 -> 3 | V29: 117831
A30: 2002 | B30: H | C30: =+SUM(D10:H10) -> 4955 | D30: =+I10 -> 368 | E30: =+J10 -> 422 | F30: =+K10 -> 762 | G30: =+L10 -> 921 | H30: =+M10 -> 950 | I30: =+N10 -> 974 | J30: =+O10 -> 1180 | K30: =+P10 -> 1519 | ... U30: =+Z10 -> 12 | V30: 117227
A31: 2003 | B31: H | C31: =+SUM(D11:H11) -> 5708 | D31: =+I11 -> 378 | E31: =+J11 -> 423 | F31: =+K11 -> 702 | G31: =+L11 -> 876 | H31: =+M11 -> 896 | I31: =+N11 -> 957 | J31: =+O11 -> 1144 | K31: =+P11 -> 1492 | ... U31: =+Z11 -> 4 | V31: 121864
A32: 2004 | B32: H | C32: =+SUM(D12:H12) -> 4932 | D32: =+I12 -> 370 | E32: =+J12 -> 425 | F32: =+K12 -> 712 | G32: =+L12 -> 821 | H32: =+M12 -> 846 | I32: =+N12 -> 899 | J32: =+O12 -> 1077 | K32: =+P12 -> 1427 | ... U32: =+Z12 -> 10 | V32: 110293
A33: 2005 | B33: H | C33: =+SUM(D13:H13) -> 4651 | D33: =+I13 -> 339 | E33: =+J13 -> 347 | F33: =+K13 -> 645 | G33: =+L13 -> 814 | H33: =+M13 -> 835 | I33: =+N13 -> 872 | J33: =+O13 -> 1109 | K33: =+P13 -> 1420 | ... U33: =+Z13 -> 13 | V33: 110672
A34: 2006 | B34: H | C34: =+SUM(D14:H14) -> 4309 | D34: =+I14 -> 351 | E34: =+J14 -> 413 | F34: =+K14 -> 710 | G34: =+L14 -> 760 | H34: =+M14 -> 900 | I34: =+N14 -> 952 | J34: =+O14 -> 1084 | K34: =+P14 -> 1504 | ... U34: =+Z14 -> 7 | V34: 105948
... A39: 2011 | B39: H | C39: =+SUM(D19:H19) -> 4527 | D39: =+I19 -> 286 | E39: =+J19 -> 373 | F39: =+K19 -> 681 | G39: =+L19 -> 790 | H39: =+M19 -> 944 | I39: =+N19 -> 1141 | J39: =+O19 -> 1266 | K39: =+P19 -> 1596 | ... U39: =+Z19 -> 6 | V39: 98136
C41: Año | D41: 1995 | E41: 1996 | F41: 1997 | G41: 1998 | H41: 1999 | I41: 2000 | J41: 2001 | K41: 2002 | L41: 2003 | M41: 2004 | N41: 2005 | O41: 2006 | P41: 2007 | Q41: 2008 | R41: 2009 | S41: 2010 | T41: 2011
C42: -1 | D42: 5291 | E42: 5083 | F42: 4745 | G42: 4577 | H42: 4273 | I42: 4027 | J42: 3978 | K42: 3973 | L42: 4428 | M42: 3955 | N42: 3889 | O42: 3570 | P42: 3476 | Q42: 3526 | R42: 3689 | S42: 3863 | T42: 3867
C43: 1 | D43: 637 | E43: 740 | F43: 582 | G43: 608 | H43: 564 | I43: 568 | J43: 581 | K43: 545 | L43: 714 | M43: 501 | N43: 402 | O43: 391 | P43: 364 | Q43: 293 | R43: 308 | S43: 290 | T43: 297
C44: 2 | D44: 249 | E44: 279 | F44: 256 | G44: 255 | H44: 229 | I44: 220 | J44: 235 | K44: 187 | L44: 282 | M44: 208 | N44: 171 | O44: 148 | P44: 165 | Q44: 149 | R44: 176 | S44: 138 | T44: 164
C45: 3 | D45: 157 | E45: 162 | F45: 158 | G45: 162 | H45: 163 | I45: 144 | J45: 127 | K45: 139 | L45: 176 | M45: 144 | N45: 107 | O45: 101 | P45: 115 | Q45: 105 | R45: 113 | S45: 88 | T45: 106
C46: 4 | D46: 98 | E46: 129 | F46: 130 | G46: 108 | H46: 119 | I46: 102 | J46: 112 | K46: 111 | L46: 108 | M46: 124 | N46: 82 | O46: 99 | P46: 80 | Q46: 80 | R46: 79 | S46: 104 | T46: 93

Sheet Población M
B1: Fuente: Instituto Nacional de Estadística, (INE)
B2: Año | C2: Total | D2: Grupo de edad | E2: Hombres | F2: Mujeres | H2: Suma de Hombres | I2: Rótulos de columna
B3: 2011 | C3: 27227930 | D3: Total | E3: 13549752 | F3: 13678178 | H3: Rótulos de fila | I3: 00 - 04 | J3: 05 - 09 | K3: 10 - 14 | L3: 15 - 19 | M3: 20 - 24 | N3: 25 - 29 | O3: 30 - 34 | P3: 35 - 39 | Q3: 40 - 44 | R3: 45 - 49 | S3: 50 - 54 | T3: 55 - 59 | U3: 60 - 64 | V3: 65 - 69 | W3: 70 - 74 | X3: 75 - 79 | Y3: 80 - 84 | Z3: 85 - 89 | AA3: 85 y más | AB3: 90 - 94 | AC3: 90 y más | AD3: 95 y más | AE3: Total | AF3: Total general
B4: 2011 | C4: 2437631 | D4: 00 - 04 | E4: 1254208 | F4: 1183423 | H4: 1926 | I4: 192264 | J4: 172610 | K4: 168508 | L4: 148420 | M4: 130616 | N4: 119159 | O4: 102748 | P4: 80202 | Q4: 71605 | R4: 54991 | S4: 47993 | T4: 23661 | U4: 21794 | V4: 11530 | W4: 8712 | X4: 5228 | Y4: 3869 | AA4: 50680 | AE4: 1414590 | AF4: 2829180 | AG4: =+SUM(Z4:AD4) -> 50680 | AH4: =+Y4 -> 3869
B5: 2011 | C5: 2402364 | D5: 05 - 09 | E5: 1236217 | F5: 1166147 | H5: 1936 | I5: 240120 | J5: 241375 | K5: 214908 | L5: 164434 | M5: 158839 | N5: 135653 | O5: 104115 | P5: 98195 | Q5: 80264 | R5: 65393 | S5: 52251 | T5: 32890 | U5: 28734 | V5: 13591 | W5: 9200 | X5: 4498 | Y5: 3407 | AA5: 4263 | AE5: 1652130 | AF5: 3304260 | AG5: =+SUM(Z5:AD5) -> 4263 | AH5: =+Y5 -> 3407 | AI5: =+AG5/(AG5+AH5) -> 0.55580183
B6: 2011 | C6: 2516779 | D6: 10 - 14 | E6: 1298191 | F6: 1218588 | H6: 1941 | I6: 292473 | J6: 266753 | K6: 246333 | L6: 190892 | M6: 182714 | N6: 154307 | O6: 124440 | P6: 106042 | Q6: 93873 | R6: 79815 | S6: 57600 | T6: 38303 | U6: 31757 | V6: 16089 | W6: 10478 | X6: 5521 | Y6: 4079 | AA6: 7076 | AE6: 1908545 | AF6: 3817090 | AG6: =+SUM(Z6:AD6) -> 7076 | AH6: =+Y6 -> 4079 | AI6: =+AG6/(AG6+AH6) -> 0.63433438
B7: 2011 | C7: 2641320 | D7: 15 - 19 | E7: 1336159 | F7: 1305161 | H7: 1950 | I7: 432681 | J7: 352758 | K7: 298518 | L7: 244191 | M7: 236133 | N7: 202418 | O7: 170176 | P7: 156330 | Q7: 124964 | R7: 97832 | S7: 82619 | T7: 52359 | U7: 41518 | V7: 22025 | W7: 15491 | X7: 7802 | Y7: 5873 | AA7: 4125 | AC7: 4678 | AE7: 2552491 | AF7: 5104982 | AG7: =+SUM(Z7:AD7) -> 8803 | AH7: =+Y7 -> 5873 | AI7: =+AG7/(AG7+AH7) -> 0.59982284
B8: 2011 | C8: 2560649 | D8: 20 - 24 | E8: 1280125 | F8: 1280524 | H8: 1961 | I8: 698316 | J8: 591273 | K8: 458372 | L8: 340465 | M8: 311678 | N8: 283008 | O8: 264861 | P8: 210638 | Q8: 174323 | R8: 146041 | S8: 112531 | T8: 84211 | U8: 62356 | V8: 36152 | W8: 21657 | X8: 12601 | Y8: 7431 | AA8: 5808 | AE8: 3821722 | AF8: 7643444 | AG8: =+SUM(Z8:AD8) -> 5808 | AH8: =+Y8 -> 7431 | AI8: =+AG8/(AG8+AH8) -> 0.43870383
B9: 2011 | C9: 2344332 | D9: 25 - 29 | E9: 1159400 | F9: 1184932 | H9: 1971 | I9: 878007 | J9: 851071 | K9: 728788 | L9: 601038 | M9: 464191 | N9: 336538 | O9: 290210 | P9: 269941 | Q9: 242951 | R9: 191292 | S9: 153806 | T9: 115284 | U9: 93197 | V9: 57256 | W9: 40723 | X9: 19900 | Y9: 12470 | AA9: 10494 | AE9: 5357157 | AF9: 10714314 | AG9: =+SUM(Z9:AD9) -> 10494 | AH9: =+Y9 -> 12470 | AI9: =+AG9/(AG9+AH9) -> 0.45697614
B10: 2011 | C10: 2219741 | D10: 30 - 34 | E10: 1105617 | F10: 1114124 | H10: 1981 | I10: 1066796 | J10: 966393 | K10: 903908 | L10: 822575 | M10: 716784 | N10: 610993 | O10: 492405 | P10: 363267 | Q10: 303292 | R10: 258065 | S10: 225406 | T10: 170190 | U10: 127759 | V10: 92020 | W10: 63663 | X10: 38076 | Y10: 38220 | AE10: 7259812 | AF10: 14519624 | AG10: =+SUM(Z10:AD10) -> 0 | AH10: =+Y10 -> 38220 | AJ10: =+AVERAGE(AI5:AI13) -> 0.49264189
B11: 2011 | C11: 1905253 | D11: 35 - 39 | E11: 942311 | F11: 962942 | H11: 1990 | I11: 1194896 | J11: 1146087 | K11: 1087702 | L11: 968497 | M11: 858225 | N11: 772081 | O11: 671020 | P11: 570519 | Q11: 437768 | R11: 318990 | S11: 268059 | T11: 213658 | U11: 182223 | V11: 122834 | W11: 88974 | X11: 57796 | Y11: 37974 | AA11: 22454 | AE11: 9019757 | AF11: 18039514 | AG11: =+SUM(Z11:AD11) -> 22454 | AH11: =+Y11 -> 37974 | AI11: =+AG11/(AG11+AH11) -> 0.37158271
B12: 2011 | C12: 1755490 | D12: 40 - 44 | E12: 873509 | F12: 881981 | H12: 2001 | I12: 1282639 | J12: 1367727 | K12: 1281342 | L12: 1164429 | M12: 1080653 | N12: 924446 | O12: 863034 | P12: 772881 | Q12: 695516 | R12: 564987 | S12: 452112 | T12: 297806 | U12: 240296 | V12: 178264 | W12: 140060 | X12: 93302 | Y12: 52605 | AA12: 43171 | AE12: 11495270 | AF12: 22990540 | AG12: =+SUM(Z12:AD12) -> 43171 | AH12: =+Y12 -> 52605 | AI12: =+AG12/(AG12+AH12) -> 0.45074967
B13: 2011 | C13: 1528781 | D13: 45 - 49 | E13: 747704 | F13: 781077 | H13: 2011 | I13: 1254208 | J13: 1236217 | K13: 1298191 | L13: 1336159 | M13: 1280125 | N13: 1159400 | O13: 1105617 | P13: 942311 | Q13: 873509 | R13: 747704 | S13: 651255 | T13: 530935 | U13: 407656 | V13: 267691 | W13: 189285 | X13: 130126 | Y13: 78996 | Z13: 40560 | AB13: 14875 | AD13: 4932 | AE13: 13549752 | AF13: 27099504 | AG13: =+SUM(Z13:AD13) -> 60367 | AH13: =+Y13 -> 78996 | AI13: =+AG13/(AG13+AH13) -> 0.43316375
B14: 2011 | C14: 1337934 | D14: 50 - 54 | E14: 651255 | F14: 686679 | H14: Total general | I14: 7532400 | J14: 7192264 | K14: 6686570 | L14: 5981100 | M14: 5419958 | N14: 4698003 | O14: 4188626 | P14: 3570326 | Q14: 3098065 | R14: 2525110 | S14: 2103632 | T14: 1559297 | U14: 1237290 | V14: 817452 | W14: 588243 | X14: 374850 | Y14: 244924 | Z14: 40560 | AA14: 148071 | AB14: 14875 | AC14: 4678 | AD14: 4932 | AE14: 58031226 | AF14: 116062452
B15: 2011 | C15: 1108799 | D15: 55 - 59 | E15: 530935 | F15: 577864 | K15: =-515.2255 -> -515.2255 | W15: -1585.7186
B16: 2011 | C16: 848358 | D16: 60 - 64 | E16: 407656 | F16: 440702 | K16: 2064241.8 | W16: 6348752.1
B17: 2011 | C17: 568688 | D17: 65 - 69 | E17: 267691 | F17: 300997 | K17: -2.0663016e+09 | W17: -6.3532663e+09
B18: 2011 | C18: 410455 | D18: 70 - 74 | E18: 189285 | F18: 221170 | H18: Rótulos de fila | I18: 00 - 04 | K18: Inter | T18: Rótulos de fila | U18: 05 - 09 | W18: Inter
B19: 2011 | C19: 292992 | D19: 75 - 79 | E19: 130126 | F19: 162866 | H19: 1990 | I19: 1194896 | J19: 1995 | K19: =+J19^2*$K$15+J19*$K$16+$K$17 -> 1250399.6 | T19: 1990 | U19: 1146087 | V19: 1995 | W19: =+V19^2*$W$15+V19*$W$16+$W$17 -> 1294462.7
B20: 2011 | C20: 188895 | D20: 80 - 84 | E20: 78996 | F20: 109899 | H20: 2001 | I20: 1282639 | J20: 1996 | K20: =+J20^2*$K$15+J20*$K$16+$K$17 -> 1258376.4 | T20: 2001 | U20: 1367727 | V20: 1996 | W20: =+V20^2*$W$15+V20*$W$16+$W$17 -> 1314611.8
B21: 2011 | C21: 104141 | D21: 85 - 89 | E21: 40560 | F21: 63581 | H21: 2011 | I21: 1254208 | J21: 1997 | K21: =+J21^2*$K$15+J21*$K$16+$K$17 -> 1265322.8 | T21: 2011 | U21: 1236217 | V21: 1997 | W21: =+V21^2*$W$15+V21*$W$16+$W$17 -> 1331589.6
B22: 2011 | C22: 40370 | D22: 90 - 94 | E22: 14875 | F22: 25495 | J22: 1998 | K22: =+J22^2*$K$15+J22*$K$16+$K$17 -> 1271238.7 | V22: 1998 | W22: =+V22^2*$W$15+V22*$W$16+$W$17 -> 1345395.8
B23: 2011 | C23: 14958 | D23: 95 y más | E23: 4932 | F23: 10026 | J23: 1999 | K23: =+J23^2*$K$15+J23*$K$16+$K$17 -> 1276124.1 | V23: 1999 | W23: =+V23^2*$W$15+V23*$W$16+$W$17 -> 1356030.7
B24: 2001 | C24: 23232553 | D24: Total | E24: 11495270 | F24: 11737283 | J24: 2000 | K24: =+J24^2*$K$15+J24*$K$16+$K$17 -> 1279979.1 | V24: 2000 | W24: =+V24^2*$W$15+V24*$W$16+$W$17 -> 1363494.1
B25: 2001 | C25: 2501894 | D25: 00 - 04 | E25: 1282639 | F25: 1219255 | J25: 2001 | K25: =+J25^2*$K$15+J25*$K$16+$K$17 -> 1282803.7 | V25: 2001 | W25: =+V25^2*$W$15+V25*$W$16+$W$17 -> 1367786
B26: 2001 | C26: 2680308 | D26: 05 - 09 | E26: 1367727 | F26: 1312581 | J26: 2002 | K26: =+J26^2*$K$15+J26*$K$16+$K$17 -> 1284597.8 | V26: 2002 | W26: =+V26^2*$W$15+V26*$W$16+$W$17 -> 1368906.6
B27: 2001 | C27: 2535766 | D27: 10 - 14 | E27: 1281342 | F27: 1254424 | J27: 2003 | K27: =+J27^2*$K$15+J27*$K$16+$K$17 -> 1285361.4 | V27: 2003 | W27: =+V27^2*$W$15+V27*$W$16+$W$17 -> 1366855.6
B28: 2001 | C28: 2319853 | D28: 15 - 19 | E28: 1164429 | F28: 1155424 | J28: 2004 | K28: =+J28^2*$K$15+J28*$K$16+$K$17 -> 1285094.6 | V28: 2004 | W28: =+V28^2*$W$15+V28*$W$16+$W$17 -> 1361633.3
B29: 2001 | C29: 2185621 | D29: 20 - 24 | E29: 1080653 | F29: 1104968 | J29: 2005 | K29: =+J29^2*$K$15+J29*$K$16+$K$17 -> 1283797.3 | V29: 2005 | W29: =+V29^2*$W$15+V29*$W$16+$W$17 -> 1353239.5
B30: 2001 | C30: 1888838 | D30: 25 - 29 | E30: 924446 | F30: 964392 | J30: 2006 | K30: =+J30^2*$K$15+J30*$K$16+$K$17 -> 1281469.6 | V30: 2006 | W30: =+V30^2*$W$15+V30*$W$16+$W$17 -> 1341674.3
B31: 2001 | C31: 1762621 | D31: 30 - 34 | E31: 863034 | F31: 899587 | J31: 2007 | K31: =+J31^2*$K$15+J31*$K$16+$K$17 -> 1278111.5 | V31: 2007 | W31: =+V31^2*$W$15+V31*$W$16+$W$17 -> 1326937.6
B32: 2001 | C32: 1593742 | D32: 35 - 39 | E32: 772881 | F32: 820861 | J32: 2008 | K32: =+J32^2*$K$15+J32*$K$16+$K$17 -> 1273722.9 | V32: 2008 | W32: =+V32^2*$W$15+V32*$W$16+$W$17 -> 1309029.5
B33: 2001 | C33: 1428506 | D33: 40 - 44 | E33: 695516 | F33: 732990 | J33: 2009 | K33: =+J33^2*$K$15+J33*$K$16+$K$17 -> 1268303.8 | V33: 2009 | W33: =+V33^2*$W$15+V33*$W$16+$W$17 -> 1287950
... B35: 2001 | C35: 925449 | D35: 50 - 54 | E35: 452112 | F35: 473337 | J35: 2011 | K35: =+J35^2*$K$15+J35*$K$16+$K$17 -> 1254374.3 | V35: 2011 | W35: =+V35^2*$W$15+V35*$W$16+$W$17 -> 1236276.6
B36: 2001 | C36: 619029 | D36: 55 - 59 | E36: 297806 | F36: 321223
B37: 2001 | C37: 503568 | D37: 60 - 64 | E37: 240296 | F37: 263272 | K37: =-758.0351 -> -758.0351 | W37: =-13.0251 -> -13.0251
B38: 2001 | C38: 383306 | D38: 65 - 69 | E38: 178264 | F38: 205042 | K38: 3042921.6 | W38: 72203.934
B39: 2001 | C39: 304303 | D39: 70 - 74 | E39: 140060 | F39: 164243 | K39: -3.0524316e+09 | W39: -91246873
B40: 2001 | C40: 206737 | D40: 75 - 79 | E40: 93302 | F40: 113435 | H40: Rótulos de fila | I40: 10 - 14 | K40: Inter | T40: Rótulos de fila | U40: 20 - 24 | W40: Inter
B41: 2001 | C41: 124442 | D41: 80 - 84 | E41: 52605 | F41: 71837 | H41: 1990 | I41: 1087702 | J41: 1995 | K41: =+J41^2*$K$37+J41*$K$38+$K$39 -> 1198321.6 | T41: 1990 | U41: 858225 | V41: 1995 | W41: =+V41^2*$W$37+V41*$W$38+$W$39 -> 959752.13
...

Sheet Población F
B1: Fuente: Instituto Nacional de Estadística, (INE)
B2: Año | C2: Total | D2: Grupo de edad | E2: Hombres | F2: Mujeres | H2: Suma de Mujeres | I2: Rótulos de columna
B3: 2011 | C3: 27227930 | D3: Total | E3: 13549752 | F3: 13678178 | H3: Rótulos de fila | I3: 00 - 04 | J3: 05 - 09 | K3: 10 - 14 | L3: 15 - 19 | M3: 20 - 24 | N3: 25 - 29 | O3: 30 - 34 | P3: 35 - 39 | Q3: 40 - 44 | R3: 45 - 49 | S3: 50 - 54 | T3: 55 - 59 | U3: 60 - 64 | V3: 65 - 69 | W3: 70 - 74 | X3: 75 - 79 | Y3: 80 - 84 | Z3: 85 - 89 | AA3: 85 y más | AB3: 90 - 94 | AC3: 90 y más | AD3: 95 y más | AE3: Total | AF3: Total general
B4: 2011 | C4: 2437631 | D4: 00 - 04 | E4: 1254208 | F4: 1183423 | H4: 1926 | I4: 190972 | J4: 165762 | K4: 158273 | L4: 160827 | M4: 142983 | N4: 133208 | O4: 113864 | P4: 87390 | Q4: 79130 | R4: 51924 | S4: 50712 | T4: 22696 | U4: 26007 | V4: 13146 | W4: 11803 | X4: 6288 | Y4: 6011 | AA4: 55134 | AE4: 1476130 | AF4: 2952260 | AG4: =+SUM(Z4:AD4) -> 55134 | AH4: =+Y4 -> 6011
B5: 2011 | C5: 2402364 | D5: 05 - 09 | E5: 1236217 | F5: 1166147 | H5: 1936 | I5: 233508 | J5: 230133 | K5: 197207 | L5: 184606 | M5: 174231 | N5: 149412 | O5: 113664 | P5: 101996 | Q5: 88325 | R5: 59809 | S5: 58908 | T5: 32149 | U5: 37974 | V5: 16061 | W5: 14048 | X5: 6428 | Y5: 6795 | AA5: 6963 | AE5: 1712217 | AF5: 3424434 | AG5: =+SUM(Z5:AD5) -> 6963 | AH5: =+Y5 -> 6795 | AI5: =+AG5/(AG5+AH5) -> 0.50610554
B6: 2011 | C6: 2516779 | D6: 10 - 14 | E6: 1298191 | F6: 1218588 | H6: 1941 | I6: 285520 | J6: 255893 | K6: 226819 | L6: 211629 | M6: 190573 | N6: 167346 | O6: 127028 | P6: 109237 | Q6: 96588 | R6: 72259 | S6: 60707 | T6: 38298 | U6: 40855 | V6: 19163 | W6: 16442 | X6: 7938 | Y6: 7424 | AA6: 8507 | AE6: 1942226 | AF6: 3884452 | AG6: =+SUM(Z6:AD6) -> 8507 | AH6: =+Y6 -> 7424 | AI6: =+AG6/(AG6+AH6) -> 0.53399033
B7: 2011 | C7: 2641320 | D7: 15 - 19 | E7: 1336159 | F7: 1305161 | H7: 1950 | I7: 415067 | J7: 334560 | K7: 276204 | L7: 252375 | M7: 237615 | N7: 198196 | O7: 157437 | P7: 145213 | Q7: 114644 | R7: 86936 | S7: 82117 | T7: 49520 | U7: 50948 | V7: 25894 | W7: 22789 | X7: 10996 | Y7: 10687 | AA7: 7748 | AC7: 3401 | AE7: 2482347 | AF7: 4964694 | AG7: =+SUM(Z7:AD7) -> 11149 | AH7: =+Y7 -> 10687 | AI7: =+AG7/(AG7+AH7) -> 0.51057886
B8: 2011 | C8: 2560649 | D8: 20 - 24 | E8: 1280125 | F8: 1280524 | H8: 1961 | I8: 675780 | J8: 572047 | K8: 443509 | L8: 339171 | M8: 306733 | N8: 267874 | O8: 237836 | P8: 194534 | Q8: 157264 | R8: 134760 | S8: 106242 | T8: 83098 | U8: 69358 | V8: 41570 | W8: 29358 | X8: 18348 | Y8: 13301 | AA8: 11494 | AE8: 3702277 | AF8: 7404554 | AG8: =+SUM(Z8:AD8) -> 11494 | AH8: =+Y8 -> 13301 | AI8: =+AG8/(AG8+AH8) -> 0.4635612
B9: 2011 | C9: 2344332 | D9: 25 - 29 | E9: 1159400 | F9: 1184932 | H9: 1971 | I9: 856531 | J9: 803961 | K9: 727073 | L9: 626659 | M9: 490222 | N9: 356647 | O9: 292766 | P9: 267555 | Q9: 225639 | R9: 179750 | S9: 149714 | T9: 116485 | U9: 96773 | V9: 62567 | W9: 47674 | X9: 25899 | Y9: 19380 | AA9: 19070 | AE9: 5364365 | AF9: 10728730 | AG9: =+SUM(Z9:AD9) -> 19070 | AH9: =+Y9 -> 19380 | AI9: =+AG9/(AG9+AH9) -> 0.49596879
B10: 2011 | C10: 2219741 | D10: 30 - 34 | E10: 1105617 | F10: 1114124 | H10: 1981 | I10: 1031843 | J10: 939654 | K10: 888675 | L10: 823768 | M10: 732288 | N10: 625936 | O10: 494361 | P10: 364497 | Q10: 298413 | R10: 254438 | S10: 220359 | T10: 169949 | U10: 133137 | V10: 102739 | W10: 74721 | X10: 47278 | Y10: 54867 | AE10: 7256923 | AF10: 14513846 | AG10: =+SUM(Z10:AD10) -> 0 | AH10: =+Y10 -> 54867 | AJ10: =+AVERAGE(AI5:AI13) -> 0.48368085
B11: 2011 | C11: 1905253 | D11: 35 - 39 | E11: 942311 | F11: 962942 | H11: 1990 | I11: 1148163 | J11: 1107711 | K11: 1059292 | L11: 954017 | M11: 866962 | N11: 797461 | O11: 695674 | P11: 593061 | Q11: 450116 | R11: 325227 | S11: 276801 | T11: 221681 | U11: 193315 | V11: 135951 | W11: 102688 | X11: 72986 | Y11: 50004 | AA11: 34398 | AE11: 9085508 | AF11: 18171016 | AG11: =+SUM(Z11:AD11) -> 34398 | AH11: =+Y11 -> 50004 | AI11: =+AG11/(AG11+AH11) -> 0.40754958
B12: 2011 | C12: 1755490 | D12: 40 - 44 | E12: 873509 | F12: 881981 | H12: 2001 | I12: 1219255 | J12: 1312581 | K12: 1254424 | L12: 1155424 | M12: 1104968 | N12: 964392 | O12: 899587 | P12: 820861 | Q12: 732990 | R12: 594756 | S12: 473337 | T12: 321223 | U12: 263272 | V12: 205042 | W12: 164243 | X12: 113435 | Y12: 71837 | AA12: 65656 | AE12: 11737283 | AF12: 23474566 | AG12: =+SUM(Z12:AD12) -> 65656 | AH12: =+Y12 -> 71837 | AI12: =+AG12/(AG12+AH12) -> 0.47752249
B13: 2011 | C13: 1528781 | D13: 45 - 49 | E13: 747704 | F13: 781077 | H13: 2011 | I13: 1183423 | J13: 1166147 | K13: 1218588 | L13: 1305161 | M13: 1280524 | N13: 1184932 | O13: 1114124 | P13: 962942 | Q13: 881981 | R13: 781077 | S13: 686679 | T13: 577864 | U13: 440702 | V13: 300997 | W13: 221170 | X13: 162866 | Y13: 109899 | Z13: 63581 | AB13: 25495 | AD13: 10026 | AE13: 13678178 | AF13: 27356356 | AG13: =+SUM(Z13:AD13) -> 99102 | AH13: =+Y13 -> 109899 | AI13: =+AG13/(AG13+AH13) -> 0.47416998
B14: 2011 | C14: 1337934 | D14: 50 - 54 | E14: 651255 | F14: 686679 | H14: Total general | I14: 7240062 | J14: 6888449 | K14: 6450064 | L14: 6013637 | M14: 5527099 | N14: 4845404 | O14: 4246341 | P14: 3647286 | Q14: 3125090 | R14: 2540936 | S14: 2165576 | T14: 1632963 | U14: 1352341 | V14: 923130 | W14: 704936 | X14: 472462 | Y14: 350205 | Z14: 63581 | AA14: 208970 | AB14: 25495 | AC14: 3401 | AD14: 10026 | AE14: 58437454 | AF14: 116874908
B15: 2011 | C15: 1108799 | D15: 55 - 59 | E15: 530935 | F15: 577864 | K15: -478.3861 | W15: -1584.1879
B16: 2011 | C16: 848358 | D16: 60 - 64 | E16: 407656 | F16: 440702 | K16: 1915702 | W16: 6341118.4
B17: 2011 | C17: 568688 | D17: 65 - 69 | E17: 267691 | F17: 300997 | K17: -1.9166419e+09 | W17: -6.3441754e+09
B18: 2011 | C18: 410455 | D18: 70 - 74 | E18: 189285 | F18: 221170 | H18: Rótulos de fila | I18: 00 - 04 | K18: Inter | T18: Rótulos de fila | U18: 05 - 09 | W18: Inter
B19: 2011 | C19: 292992 | D19: 75 - 79 | E19: 130126 | F19: 162866 | H19: 1990 | I19: 1148163 | J19: 1995 | K19: =+J19^2*$K$15+J19*$K$16+$K$17 -> 1195016.9 | T19: 1990 | U19: 1107711 | V19: 1995 | W19: =+V19^2*$W$15+V19*$W$16+$W$17 -> 1248274.9
B20: 2011 | C20: 188895 | D20: 80 - 84 | E20: 78996 | F20: 109899 | H20: 2001 | I20: 1219255 | J20: 1996 | K20: =+J20^2*$K$15+J20*$K$16+$K$17 -> 1201480 | T20: 2001 | U20: 1312581 | V20: 1996 | W20: =+V20^2*$W$15+V20*$W$16+$W$17 -> 1266899.4
B21: 2011 | C21: 104141 | D21: 85 - 89 | E21: 40560 | F21: 63581 | H21: 2011 | I21: 1183423 | J21: 1997 | K21: =+J21^2*$K$15+J21*$K$16+$K$17 -> 1206986.3 | T21: 2011 | U21: 1166147 | V21: 1997 | W21: =+V21^2*$W$15+V21*$W$16+$W$17 -> 1282355.5
B22: 2011 | C22: 40370 | D22: 90 - 94 | E22: 14875 | F22: 25495 | J22: 1998 | K22: =+J22^2*$K$15+J22*$K$16+$K$17 -> 1211535.9 | V22: 1998 | W22: =+V22^2*$W$15+V22*$W$16+$W$17 -> 1294643.2
B23: 2011 | C23: 14958 | D23: 95 y más | E23: 4932 | F23: 10026 | J23: 1999 | K23: =+J23^2*$K$15+J23*$K$16+$K$17 -> 1215128.7 | V23: 1999 | W23: =+V23^2*$W$15+V23*$W$16+$W$17 -> 1303762.5
B24: 2001 | C24: 23232553 | D24: Total | E24: 11495270 | F24: 11737283 | J24: 2000 | K24: =+J24^2*$K$15+J24*$K$16+$K$17 -> 1217764.7 | V24: 2000 | W24: =+V24^2*$W$15+V24*$W$16+$W$17 -> 1309713.5
B25: 2001 | C25: 2501894 | D25: 00 - 04 | E25: 1282639 | F25: 1219255 | J25: 2001 | K25: =+J25^2*$K$15+J25*$K$16+$K$17 -> 1219443.9 | V25: 2001 | W25: =+V25^2*$W$15+V25*$W$16+$W$17 -> 1312496.1
B26: 2001 | C26: 2680308 | D26: 05 - 09 | E26: 1367727 | F26: 1312581 | J26: 2002 | K26: =+J26^2*$K$15+J26*$K$16+$K$17 -> 1220166.4 | V26: 2002 | W26: =+V26^2*$W$15+V26*$W$16+$W$17 -> 1312110.3
